Workbook

Sheet ΟΔΗΓΙΕΣ
A1: 3ο ΓΥΜΝΑΣΙΟ ΠΟΛΙΧΝΗΣ · ΗΜΕΡΟΛΟΓΙΟ ΔΡΑΣΕΩΝ · ΣΧΟΛΙΚΟ ΕΤΟΣ 2026-27
A3: Έτος έναρξης σχολικού έτους: | B3: 2026
A4: Το μόνο κελί που αλλάζεις για να μεταφερθεί όλο το αρχείο στην επόμενη χρονιά.
A6: ΠΩΣ ΔΟΥΛΕΥΕΙ
A7: 1. | B7: Γράφεις κάθε δράση ΜΟΝΟ στο φύλλο ΔΡΑΣΕΙΣ, μία γραμμή ανά δράση.
A8: 2. | B8: Το φύλλο ΑΦΙΣΑ_ΕΠΙΛΟΓΗΣ ενημερώνεται αυτόματα.
A9: 3. | B9: Το χρώμα κάθε ημέρας βγαίνει από τη στήλη «Κατηγορία». Διάλεξε από τη λίστα του κελιού.
A10: 4. | B10: Νέα δράση: γράψε την στην κίτρινη (πρώτη κενή) γραμμή στο τέλος – αναλυτικά βήμα–βήμα πιο κάτω.
A12: ΒΗΜΑ–ΒΗΜΑ: ΠΩΣ ΠΡΟΣΘΕΤΩ ΜΙΑ ΝΕΑ ΔΡΑΣΗ
A13: Βήμα 1 | B13: Πήγαινε στο φύλλο ΔΡΑΣΕΙΣ (καρτέλα κάτω κάτω στην οθόνη). Όλες οι δράσεις γράφονται ΜΟΝΟ εκεί.
A14: Βήμα 2 | B14: Κατέβα στο τέλος του πίνακα: πάτα Ctrl + Κάτω βέλος. Η πρώτη κενή γραμμή είναι βαμμένη ανοιχτό κίτρινο – αυτή είναι η σειρά σου.
A15: Βήμα 3 | B15: Συμπλήρωσε τα κελιά A έως G αυτής της κίτρινης γραμμής (τι ακριβώς γράφεις σε κάθε στήλη: πιο κάτω). Μην προσθέτεις γραμμή στη μέση του πίνακα.
A16: Βήμα 4 | B16: Μόλις διαλέξεις Κατηγορία, η γραμμή παίρνει το χρώμα της και η επόμενη κενή γραμμή γίνεται η νέα «κίτρινη». Αν δεν αλλάξει χρώμα, κάτι λείπει (συνήθως η ημερομηνία).
A17: Βήμα 5 | B17: Βάλ' τες στη σειρά: κλικ σε ένα κελί της στήλης ΗΜΕΡΟΜΗΝΙΑ → βελάκι στην κεφαλίδα «ΗΜΕΡΟΜΗΝΙΑ» → Αύξουσα ταξινόμηση (παλαιότερο → νεότερο). Τέλος, δες στο ΑΦΙΣΑ_ΕΠΙΛΟΓΗΣ ότι η δράση εμφανίστηκε στη σωστή μέρα.
A19: ΤΙ ΓΡΑΦΩ ΣΕ ΚΑΘΕ ΣΤΗΛΗ ΤΗΣ ΚΙΤΡΙΝΗΣ ΓΡΑΜΜΗΣ
A20: A · ΗΜΕΡΟΜΗΝΙΑ (υποχρεωτικό) | B20: Η ημέρα της δράσης, π.χ. 17/11/2026. Γράφεις 17/11/26 και μορφοποιείται μόνο του. Χωρίς ημερομηνία η γραμμή ΔΕΝ εμφανίζεται πουθενά.
A21: B · ΩΡΕΣ (προαιρετικό) | B21: Π.χ. 09:00–11:00 ή «1η–2η ώρα». Εμφανίζεται μπροστά από τον τίτλο στην αφίσα. Άφησέ το κενό αν δεν χρειάζεται (π.χ. σε αργίες).
A22: C · ΤΙΤΛΟΣ ΔΡΑΣΗΣ (υποχρεωτικό) | B22: Μία σύντομη φράση, π.χ. «Επίσκεψη στο ΝΟΗΣΙΣ». Αυτό διαβάζει ο κόσμος στην αφίσα – κράτα το ως περίπου 60 χαρακτήρες για να μην κόβεται.
A23: D · ΚΑΤΗΓΟΡΙΑ (υποχρεωτικό) | B23: Κλικ στο κελί → βελάκι δεξιά → διάλεξε μία από τις 8 έτοιμες επιλογές. ΜΗΝ γράφεις δική σου λέξη: από εδώ βγαίνει το χρώμα της ημέρας στην αφίσα (δες υπόμνημα χρωμάτων πιο κάτω).
A24: E · ΤΑΞΕΙΣ / ΤΜΗΜΑΤΑ (προαιρετικό) | B24: Π.χ. «Α1, Α2» ή «Β΄ τάξη» ή «όλο το σχολείο». Μπαίνει σε παρένθεση μετά τον τίτλο στην αφίσα. Αν μια δράση έχει διαφορετικά τμήματα σε διαφορετικές ώρες, χώρισέ τα με « / » και στις δύο στήλες με την ίδια σειρά, π.χ. ΩΡΕΣ «2η–3η ώρα / 4η–5η ώρα» και ΤΜΗΜΑΤΑ «Α1, Α2 / Α3».
A25: F · ΥΠΕΥΘΥΝΟΣ (προαιρετικό) | B25: Ο συνάδελφος που έχει την ευθύνη ή συνοδεύει. ΔΕΝ εμφανίζεται στην αφίσα – είναι μόνο για εσωτερική χρήση.
A26: G · ΣΗΜΕΙΩΣΕΙΣ (προαιρετικό) | B26: Ό,τι θέλεις να θυμάσαι: κόστος, λεωφορείο, αριθμός πρωτοκόλλου, εκκρεμότητες. ΔΕΝ εμφανίζεται στην αφίσα.
A27: H, I, J (γκρι στήλες) | B27: ΗΜΕΡΑ, ΚΛΕΙΔΙ, ΕΜΦΑΝΙΣΗ: συμπληρώνονται μόνες τους με τύπους. ΜΗΝ γράφεις και μην σβήνεις τίποτα εκεί.
A29: ΠΑΡΑΔΕΙΓΜΑ ΣΥΜΠΛΗΡΩΜΕΝΗΣ ΓΡΑΜΜΗΣ
A30: Γράφω στα κελιά: | B30: A: 17/11/2026 | B: 09:00–12:00 | C: Επίσκεψη στο ΝΟΗΣΙΣ | D: Εκδρομή / Επίσκεψη / Περίπατος | E: Β1, Β2 | F: Κ. Παπαδόπουλος | G: 2 λεωφορεία – πληρωμή ως 15/11
A31: Βγαίνει στην αφίσα: | B31: «09:00–12:00 Επίσκεψη στο ΝΟΗΣΙΣ (Β1, Β2)» στην τετράδα της 17ης Νοεμβρίου, με πράσινο φόντο (χρώμα της κατηγορίας «Εκδρομή»).
A33: ΤΙ ΝΑ ΠΡΟΣΕΞΕΙΣ
A34: Πολυήμερες δράσεις | B34: Γράψε μία γραμμή για κάθε ημέρα (αντιγραφή–επικόλληση και αλλαγή ημερομηνίας).
A35: Πάνω από 3 δράσεις/ημέρα | B35: Το ημερολόγιο δείχνει τις τρεις πρώτες. Σπάνιο, αλλά να το ξέρεις.
A36: Δύο κατηγορίες την ίδια μέρα | B36: Το χρώμα παίρνει την κατηγορία της πρώτης γραμμής εκείνης της ημέρας.
A37: Αν κόβεται κείμενο | B37: Ctrl+A → Κεντρική → Μορφή → Αυτόματη προσαρμογή ύψους γραμμής.
A38: Εκτύπωση | B38: ΑΦΙΣΑ_ΕΠΙΛΟΓΗΣ: δύο μήνες (L2, L3) → Α3 οριζόντια. ΑΦΙΣΑ_1ΜΗΝΑΣ: ημερολόγιο-πλέγμα ενός μήνα με χώρο για χειρόγραφες σημειώσεις (μήνας στο L2) → Α3 οριζόντια.
A40: ΠΡΟΣΩΠΙΚΑ ΔΕΔΟΜΕΝΑ | B40: Σε αντίγραφο που κυκλοφορεί ή αναρτάται, μη γράφεις ονόματα μαθητών – βάλε αρχικά.
A42: ΠΡΟΣΩΡΙΝΕΣ ΗΜΕΡΟΜΗΝΙΕΣ | B42: Λήξη Α΄ τετραμήνου, επιστροφή μετά το Πάσχα και λήξη μαθημάτων Γυμνασίου
B43: οριστικοποιούνται με εγκύκλιο του Υπουργείου. Είναι σημειωμένες ως εκτίμηση.
A45: ΥΠΟΜΝΗΜΑ ΧΡΩΜΑΤΩΝ
B46: Αργία / Διακοπές
B47: Εορτή / Εκκλησιασμός
B48: Εκδρομή / Επίσκεψη / Περίπατος
B49: Σύλλογος διδασκόντων
...

Sheet ΚΑΤΗΓΟΡΙΕΣ
A1: ΚΑΤΗΓΟΡΙΑ | B1: ΧΡΩΜΑ
A2: Αργία / Διακοπές
A3: Εορτή / Εκκλησιασμός
A4: Εκδρομή / Επίσκεψη / Περίπατος
A5: Σύλλογος διδασκόντων
A6: Ενημέρωση γονέων / Έλεγχοι
A7: Ορόσημο / Εξετάσεις
A8: Επιμόρφωση εκπαιδευτικών
A9: Δράση / Πρόγραμμα / Όμιλος
A11: Μην αλλάξεις τα ονόματα εδώ: πάνω τους στηρίζονται τα χρώματα σε όλα τα φύλλα.

Sheet ΔΡΑΣΕΙΣ
A1: ΗΜΕΡΟΜΗΝΙΑ | B1: ΩΡΕΣ | C1: ΤΙΤΛΟΣ ΔΡΑΣΗΣ | D1: ΚΑΤΗΓΟΡΙΑ | E1: ΤΑΞΕΙΣ / ΤΜΗΜΑΤΑ | F1: ΥΠΕΥΘΥΝΟΣ | G1: ΣΗΜΕΙΩΣΕΙΣ | H1: ΗΜΕΡΑ | I1: ΚΛΕΙΔΙ | J1: ΕΜΦΑΝΙΣΗ
A2: 46276 | C2: Αγιασμός – Έναρξη σχολικού έτους. Διαμοιρασμός σε τμήματα. | D2: Εορτή / Εκκλησιασμός | H2: =IF($A2="","",CHOOSE(WEEKDAY($A2,2),"Δευ","Τρί","Τετ","Πέμ","Παρ","Σάβ","Κυρ")) -> Παρ | I2: =IF($A2="","",$A2&"#"&COUNTIF($A$2:$A2,$A2)) -> 46276#1 | J2: =IF($A2="","",IF($B2="","",$B2&" ")&$C2&IF($E2="",""," ("&$E2&")")) -> Αγιασμός – Έναρξη σχολικού έτους. Διαμοιρασμός σε τμήματα.
A3: 46279 | C3: Έναρξη μαθημάτων | D3: Ορόσημο / Εξετάσεις | H3: =IF($A3="","",CHOOSE(WEEKDAY($A3,2),"Δευ","Τρί","Τετ","Πέμ","Παρ","Σάβ","Κυρ")) -> Δευ | I3: =IF($A3="","",$A3&"#"&COUNTIF($A$2:$A3,$A3)) -> 46279#1 | J3: =IF($A3="","",IF($B3="","",$B3&" ")&$C3&IF($E3="",""," ("&$E3&")")) -> Έναρξη μαθημάτων
A4: 46321 | C4: Αγίου Δημητρίου – Ελευθέρια Θεσσαλονίκης (τοπική αργία) | D4: Αργία / Διακοπές | H4: =IF($A4="","",CHOOSE(WEEKDAY($A4,2),"Δευ","Τρί","Τετ","Πέμ","Παρ","Σάβ","Κυρ")) -> Δευ | I4: =IF($A4="","",$A4&"#"&COUNTIF($A$2:$A4,$A4)) -> 46321#1 | J4: =IF($A4="","",IF($B4="","",$B4&" ")&$C4&IF($E4="",""," ("&$E4&")")) -> Αγίου Δημητρίου – Ελευθέρια Θεσσαλονίκης (τοπική αργία)
A5: 46322 | C5: Εορταστικές εκδηλώσεις για την 28η Οκτωβρίου (χωρίς μάθημα) | D5: Εορτή / Εκκλησιασμός | H5: =IF($A5="","",CHOOSE(WEEKDAY($A5,2),"Δευ","Τρί","Τετ","Πέμ","Παρ","Σάβ","Κυρ")) -> Τρί | I5: =IF($A5="","",$A5&"#"&COUNTIF($A$2:$A5,$A5)) -> 46322#1 | J5: =IF($A5="","",IF($B5="","",$B5&" ")&$C5&IF($E5="",""," ("&$E5&")")) -> Εορταστικές εκδηλώσεις για την 28η Οκτωβρίου (χωρίς μάθημα)
A6: 46323 | C6: Εθνική επέτειος 28ης Οκτωβρίου – Αργία | D6: Αργία / Διακοπές | H6: =IF($A6="","",CHOOSE(WEEKDAY($A6,2),"Δευ","Τρί","Τετ","Πέμ","Παρ","Σάβ","Κυρ")) -> Τετ | I6: =IF($A6="","",$A6&"#"&COUNTIF($A$2:$A6,$A6)) -> 46323#1 | J6: =IF($A6="","",IF($B6="","",$B6&" ")&$C6&IF($E6="",""," ("&$E6&")")) -> Εθνική επέτειος 28ης Οκτωβρίου – Αργία
A7: 46330 | B7: 08:45-11:15 | C7: Διαδικτυακή εκπαίδευση «Kids Save Lives» – επιμορφωτική δράση για μαθητές και εκπαιδευτικούς | D7: Δράση / Πρόγραμμα / Όμιλος | E7: Α΄ τάξη | H7: =IF($A7="","",CHOOSE(WEEKDAY($A7,2),"Δευ","Τρί","Τετ","Πέμ","Παρ","Σάβ","Κυρ")) -> Τετ | I7: =IF($A7="","",$A7&"#"&COUNTIF($A$2:$A7,$A7)) -> 46330#1 | J7: =IF($A7="","",IF($B7="","",$B7&" ")&$C7&IF($E7="",""," ("&$E7&")")) -> 08:45-11:15 Διαδικτυακή εκπαίδευση «Kids Save Lives»
A8: 46343 | C8: Εκδηλώσεις για την επέτειο του Πολυτεχνείου | D8: Εορτή / Εκκλησιασμός | H8: =IF($A8="","",CHOOSE(WEEKDAY($A8,2),"Δευ","Τρί","Τετ","Πέμ","Παρ","Σάβ","Κυρ")) -> Τρί | I8: =IF($A8="","",$A8&"#"&COUNTIF($A$2:$A8,$A8)) -> 46343#1 | J8: =IF($A8="","",IF($B8="","",$B8&" ")&$C8&IF($E8="",""," ("&$E8&")")) -> Εκδηλώσεις για την επέτειο του Πολυτεχνείου
A9: 46356 | B9: 09:00-12:30 | C9: Μουσείο Μακεδονικού Αγώνα και διαδραστική έκθεση Van Gogh – The Immersive Experience (ΔΕΘ Helexpo) | D9: Εκδρομή / Επίσκεψη / Περίπατος | E9: Γ΄ τάξη | H9: =IF($A9="","",CHOOSE(WEEKDAY($A9,2),"Δευ","Τρί","Τετ","Πέμ","Παρ","Σάβ","Κυρ")) -> Δευ | I9: =IF($A9="","",$A9&"#"&COUNTIF($A$2:$A9,$A9)) -> 46356#1 | J9: =IF($A9="","",IF($B9="","",$B9&" ")&$C9&IF($E9="",""," ("&$E9&")")) -> 09:00-12.30 Μουσείο Μακεδονικού Αγώνα και διαδραστική έκθεση Van Gogh – The Immersive Experience (ΔΕΘ Helexpo)
A10: 46379 | C10: Τελευταία ημέρα μαθημάτων πριν τις διακοπές | D10: Ορόσημο / Εξετάσεις | H10: =IF($A10="","",CHOOSE(WEEKDAY($A10,2),"Δευ","Τρί","Τετ","Πέμ","Παρ","Σάβ","Κυρ")) -> Τετ | I10: =IF($A10="","",$A10&"#"&COUNTIF($A$2:$A10,$A10)) -> 46379#1 | J10: =IF($A10="","",IF($B10="","",$B10&" ")&$C10&IF($E10="",""," ("&$E10&")")) -> Τελευταία ημέρα μαθημάτων πριν τις διακοπές
A11: 46380 | C11: Διακοπές Χριστουγέννων | D11: Αργία / Διακοπές | H11: =IF($A11="","",CHOOSE(WEEKDAY($A11,2),"Δευ","Τρί","Τετ","Πέμ","Παρ","Σάβ","Κυρ")) -> Πέμ | I11: =IF($A11="","",$A11&"#"&COUNTIF($A$2:$A11,$A11)) -> 46380#1 | J11: =IF($A11="","",IF($B11="","",$B11&" ")&$C11&IF($E11="",""," ("&$E11&")")) -> Διακοπές Χριστουγέννων
A12: 46381 | C12: Διακοπές Χριστουγέννων | D12: Αργία / Διακοπές | H12: =IF($A12="","",CHOOSE(WEEKDAY($A12,2),"Δευ","Τρί","Τετ","Πέμ","Παρ","Σάβ","Κυρ")) -> Παρ | I12: =IF($A12="","",$A12&"#"&COUNTIF($A$2:$A12,$A12)) -> 46381#1 | J12: =IF($A12="","",IF($B12="","",$B12&" ")&$C12&IF($E12="",""," ("&$E12&")")) -> Διακοπές Χριστουγέννων
A13: 46384 | C13: Διακοπές Χριστουγέννων | D13: Αργία / Διακοπές | H13: =IF($A13="","",CHOOSE(WEEKDAY($A13,2),"Δευ","Τρί","Τετ","Πέμ","Παρ","Σάβ","Κυρ")) -> Δευ | I13: =IF($A13="","",$A13&"#"&COUNTIF($A$2:$A13,$A13)) -> 46384#1 | J13: =IF($A13="","",IF($B13="","",$B13&" ")&$C13&IF($E13="",""," ("&$E13&")")) -> Διακοπές Χριστουγέννων
A14: 46385 | C14: Διακοπές Χριστουγέννων | D14: Αργία / Διακοπές | H14: =IF($A14="","",CHOOSE(WEEKDAY($A14,2),"Δευ","Τρί","Τετ","Πέμ","Παρ","Σάβ","Κυρ")) -> Τρί | I14: =IF($A14="","",$A14&"#"&COUNTIF($A$2:$A14,$A14)) -> 46385#1 | J14: =IF($A14="","",IF($B14="","",$B14&" ")&$C14&IF($E14="",""," ("&$E14&")")) -> Διακοπές Χριστουγέννων
A15: 46386 | C15: Διακοπές Χριστουγέννων | D15: Αργία / Διακοπές | H15: =IF($A15="","",CHOOSE(WEEKDAY($A15,2),"Δευ","Τρί","Τετ","Πέμ","Παρ","Σάβ","Κυρ")) -> Τετ | I15: =IF($A15="","",$A15&"#"&COUNTIF($A$2:$A15,$A15)) -> 46386#1 | J15: =IF($A15="","",IF($B15="","",$B15&" ")&$C15&IF($E15="",""," ("&$E15&")")) -> Διακοπές Χριστουγέννων
A16: 46387 | C16: Διακοπές Χριστουγέννων | D16: Αργία / Διακοπές | H16: =IF($A16="","",CHOOSE(WEEKDAY($A16,2),"Δευ","Τρί","Τετ","Πέμ","Παρ","Σάβ","Κυρ")) -> Πέμ | I16: =IF($A16="","",$A16&"#"&COUNTIF($A$2:$A16,$A16)) -> 46387#1 | J16: =IF($A16="","",IF($B16="","",$B16&" ")&$C16&IF($E16="",""," ("&$E16&")")) -> Διακοπές Χριστουγέννων
A17: 46388 | C17: Διακοπές Χριστουγέννων | D17: Αργία / Διακοπές | H17: =IF($A17="","",CHOOSE(WEEKDAY($A17,2),"Δευ","Τρί","Τετ","Πέμ","Παρ","Σάβ","Κυρ")) -> Παρ | I17: =IF($A17="","",$A17&"#"&COUNTIF($A$2:$A17,$A17)) -> 46388#1 | J17: =IF($A17="","",IF($B17="","",$B17&" ")&$C17&IF($E17="",""," ("&$E17&")")) -> Διακοπές Χριστουγέννων
A18: 46391 | C18: Διακοπές Χριστουγέννων | D18: Αργία / Διακοπές | H18: =IF($A18="","",CHOOSE(WEEKDAY($A18,2),"Δευ","Τρί","Τετ","Πέμ","Παρ","Σάβ","Κυρ")) -> Δευ | I18: =IF($A18="","",$A18&"#"&COUNTIF($A$2:$A18,$A18)) -> 46391#1 | J18: =IF($A18="","",IF($B18="","",$B18&" ")&$C18&IF($E18="",""," ("&$E18&")")) -> Διακοπές Χριστουγέννων
A19: 46392 | C19: Διακοπές Χριστουγέννων | D19: Αργία / Διακοπές | H19: =IF($A19="","",CHOOSE(WEEKDAY($A19,2),"Δευ","Τρί","Τετ","Πέμ","Παρ","Σάβ","Κυρ")) -> Τρί | I19: =IF($A19="","",$A19&"#"&COUNTIF($A$2:$A19,$A19)) -> 46392#1 | J19: =IF($A19="","",IF($B19="","",$B19&" ")&$C19&IF($E19="",""," ("&$E19&")")) -> Διακοπές Χριστουγέννων
A20: 46393 | C20: Διακοπές Χριστουγέννων | D20: Αργία / Διακοπές | H20: =IF($A20="","",CHOOSE(WEEKDAY($A20,2),"Δευ","Τρί","Τετ","Πέμ","Παρ","Σάβ","Κυρ")) -> Τετ | I20: =IF($A20="","",$A20&"#"&COUNTIF($A$2:$A20,$A20)) -> 46393#1 | J20: =IF($A20="","",IF($B20="","",$B20&" ")&$C20&IF($E20="",""," ("&$E20&")")) -> Διακοπές Χριστουγέννων
A21: 46394 | C21: Διακοπές Χριστουγέννων | D21: Αργία / Διακοπές | H21: =IF($A21="","",CHOOSE(WEEKDAY($A21,2),"Δευ","Τρί","Τετ","Πέμ","Παρ","Σάβ","Κυρ")) -> Πέμ | I21: =IF($A21="","",$A21&"#"&COUNTIF($A$2:$A21,$A21)) -> 46394#1 | J21: =IF($A21="","",IF($B21="","",$B21&" ")&$C21&IF($E21="",""," ("&$E21&")")) -> Διακοπές Χριστουγέννων
... A27: 46471 | C27: Εθνική επέτειος 25ης Μαρτίου – Αργία | D27: Αργία / Διακοπές | H27: =IF($A27="","",CHOOSE(WEEKDAY($A27,2),"Δευ","Τρί","Τετ","Πέμ","Παρ","Σάβ","Κυρ")) -> Πέμ | I27: =IF($A27="","",$A27&"#"&COUNTIF($A$2:$A27,$A27)) -> 46471#1 | J27: =IF($A27="","",IF($B27="","",$B27&" ")&$C27&IF($E27="",""," ("&$E27&")")) -> Εθνική επέτειος 25ης Μαρτίου – Αργία
A28: 46493 | B28: 2η–3η ώρα / 4η–5η ώρα | C28: Α΄ τάξη: Επιμορφωτική δράση από «Το Χαμόγελο του Παιδιού» | D28: Δράση / Πρόγραμμα / Όμιλος | E28: Α1, Α2 / Α3 | H28: =IF($A28="","",CHOOSE(WEEKDAY($A28,2),"Δευ","Τρί","Τετ","Πέμ","Παρ","Σάβ","Κυρ")) -> Παρ | I28: =IF($A28="","",$A28&"#"&COUNTIF($A$2:$A28,$A28)) -> 46493#1 | J28: =IF($A28="","",IF($B28="","",$B28&" ")&$C28&IF($E28="",""," ("&$E28&")")) -> 2η–3η ώρα / 4η–5η ώρα Α΄ τάξη: Επιμορφωτική δράση από «Το Χαμόγελο του Παιδιού» (Α1, Α2 / Α3)
A29: 46503 | C29: Διακοπές Πάσχα | D29: Αργία / Διακοπές | H29: =IF($A29="","",CHOOSE(WEEKDAY($A29,2),"Δευ","Τρί","Τετ","Πέμ","Παρ","Σάβ","Κυρ")) -> Δευ | I29: =IF($A29="","",$A29&"#"&COUNTIF($A$2:$A29,$A29)) -> 46503#1 | J29: =IF($A29="","",IF($B29="","",$B29&" ")&$C29&IF($E29="",""," ("&$E29&")")) -> Διακοπές Πάσχα
A30: 46504 | C30: Διακοπές Πάσχα | D30: Αργία / Διακοπές | H30: =IF($A30="","",CHOOSE(WEEKDAY($A30,2),"Δευ","Τρί","Τετ","Πέμ","Παρ","Σάβ","Κυρ")) -> Τρί | I30: =IF($A30="","",$A30&"#"&COUNTIF($A$2:$A30,$A30)) -> 46504#1 | J30: =IF($A30="","",IF($B30="","",$B30&" ")&$C30&IF($E30="",""," ("&$E30&")")) -> Διακοπές Πάσχα
A31: 46505 | C31: Διακοπές Πάσχα | D31: Αργία / Διακοπές | H31: =IF($A31="","",CHOOSE(WEEKDAY($A31,2),"Δευ","Τρί","Τετ","Πέμ","Παρ","Σάβ","Κυρ")) -> Τετ | I31: =IF($A31="","",$A31&"#"&COUNTIF($A$2:$A31,$A31)) -> 46505#1 | J31: =IF($A31="","",IF($B31="","",$B31&" ")&$C31&IF($E31="",""," ("&$E31&")")) -> Διακοπές Πάσχα
A32: 46506 | C32: Διακοπές Πάσχα | D32: Αργία / Διακοπές | H32: =IF($A32="","",CHOOSE(WEEKDAY($A32,2),"Δευ","Τρί","Τετ","Πέμ","Παρ","Σάβ","Κυρ")) -> Πέμ | I32: =IF($A32="","",$A32&"#"&COUNTIF($A$2:$A32,$A32)) -> 46506#1 | J32: =IF($A32="","",IF($B32="","",$B32&" ")&$C32&IF($E32="",""," ("&$E32&")")) -> Διακοπές Πάσχα
A33: 46507 | C33: Διακοπές Πάσχα | D33: Αργία / Διακοπές | H33: =IF($A33="","",CHOOSE(WEEKDAY($A33,2),"Δευ","Τρί","Τετ","Πέμ","Παρ","Σάβ","Κυρ")) -> Παρ | I33: =IF($A33="","",$A33&"#"&COUNTIF($A$2:$A33,$A33)) -> 46507#1 | J33: =IF($A33="","",IF($B33="","",$B33&" ")&$C33&IF($E33="",""," ("&$E33&")")) -> Διακοπές Πάσχα
A34: 46510 | C34: Διακοπές Πάσχα | D34: Αργία / Διακοπές | H34: =IF($A34="","",CHOOSE(WEEKDAY($A34,2),"Δευ","Τρί","Τετ","Πέμ","Παρ","Σάβ","Κυρ")) -> Δευ | I34: =IF($A34="","",$A34&"#"&COUNTIF($A$2:$A34,$A34)) -> 46510#1 | J34: =IF($A34="","",IF($B34="","",$B34&" ")&$C34&IF($E34="",""," ("&$E34&")")) -> Διακοπές Πάσχα
A35: 46511 | C35: Διακοπές Πάσχα | D35: Αργία / Διακοπές | H35: =IF($A35="","",CHOOSE(WEEKDAY($A35,2),"Δευ","Τρί","Τετ","Πέμ","Παρ","Σάβ","Κυρ")) -> Τρί | I35: =IF($A35="","",$A35&"#"&COUNTIF($A$2:$A35,$A35)) -> 46511#1 | J35: =IF($A35="","",IF($B35="","",$B35&" ")&$C35&IF($E35="",""," ("&$E35&")")) -> Διακοπές Πάσχα
A36: 46512 | C36: Διακοπές Πάσχα | D36: Αργία / Διακοπές | H36: =IF($A36="","",CHOOSE(WEEKDAY($A36,2),"Δευ","Τρί","Τετ","Πέμ","Παρ","Σάβ","Κυρ")) -> Τετ | I36: =IF($A36="","",$A36&"#"&COUNTIF($A$2:$A36,$A36)) -> 46512#1 | J36: =IF($A36="","",IF($B36="","",$B36&" ")&$C36&IF($E36="",""," ("&$E36&")")) -> Διακοπές Πάσχα
A37: 46513 | C37: Διακοπές Πάσχα | D37: Αργία / Διακοπές | H37: =IF($A37="","",CHOOSE(WEEKDAY($A37,2),"Δευ","Τρί","Τετ","Πέμ","Παρ","Σάβ","Κυρ")) -> Πέμ | I37: =IF($A37="","",$A37&"#"&COUNTIF($A$2:$A37,$A37)) -> 46513#1 | J37: =IF($A37="","",IF($B37="","",$B37&" ")&$C37&IF($E37="",""," ("&$E37&")")) -> Διακοπές Πάσχα
A38: 46514 | C38: Διακοπές Πάσχα | D38: Αργία / Διακοπές | H38: =IF($A38="","",CHOOSE(WEEKDAY($A38,2),"Δευ","Τρί","Τετ","Πέμ","Παρ","Σάβ","Κυρ")) -> Παρ | I38: =IF($A38="","",$A38&"#"&COUNTIF($A$2:$A38,$A38)) -> 46514#1 | J38: =IF($A38="","",IF($B38="","",$B38&" ")&$C38&IF($E38="",""," ("&$E38&")")) -> Διακοπές Πάσχα
A39: 46517 | C39: Επαναλειτουργία σχολείου μετά το Πάσχα (εκτίμηση) | D39: Ορόσημο / Εξετάσεις | H39: =IF($A39="","",CHOOSE(WEEKDAY($A39,2),"Δευ","Τρί","Τετ","Πέμ","Παρ","Σάβ","Κυρ")) -> Δευ | I39: =IF($A39="","",$A39&"#"&COUNTIF($A$2:$A39,$A39)) -> 46517#1 | J39: =IF($A39="","",IF($B39="","",$B39&" ")&$C39&IF($E39="",""," ("&$E39&")")) -> Επαναλειτουργία σχολείου μετά το Πάσχα (εκτίμηση)
A40: 46559 | C40: Αγίου Πνεύματος – Αργία | D40: Αργία / Διακοπές | H40: =IF($A40="","",CHOOSE(WEEKDAY($A40,2),"Δευ","Τρί","Τετ","Πέμ","Παρ","Σάβ","Κυρ")) -> Δευ | I40: =IF($A40="","",$A40&"#"&COUNTIF($A$2:$A40,$A40)) -> 46559#1 | J40: =IF($A40="","",IF($B40="","",$B40&" ")&$C40&IF($E40="",""," ("&$E40&")")) -> Αγίου Πνεύματος – Αργία
A41: 46568 | C41: Λήξη διδακτικού έτους | D41: Ορόσημο / Εξετάσεις | H41: =IF($A41="","",CHOOSE(WEEKDAY($A41,2),"Δευ","Τρί","Τετ","Πέμ","Παρ","Σάβ","Κυρ")) -> Τετ | I41: =IF($A41="","",$A41&"#"&COUNTIF($A$2:$A41,$A41)) -> 46568#1 | J41: =IF($A41="","",IF($B41="","",$B41&" ")&$C41&IF($E41="",""," ("&$E41&")")) -> Λήξη διδακτικού έτους
A42: 46349 | B42: 08:00-14:10 | C42: Επίσκεψη στο Σπήλαιο Αλιστράτης και στο ΚΠΕ Ποροΐων | D42: Εκδρομή / Επίσκεψη / Περίπατος | E42: Γ2, Γ3 | H42: =IF($A42="","",CHOOSE(WEEKDAY($A42,2),"Δευ","Τρί","Τετ","Πέμ","Παρ","Σάβ","Κυρ")) -> Δευ | I42: =IF($A42="","",$A42&"#"&COUNTIF($A$2:$A42,$A42)) -> 46349#1 | J42: =IF($A42="","",IF($B42="","",$B42&" ")&$C42&IF($E42="",""," ("&$E42&")")) -> 08:00-14:10 Επίσκεψη στο Σπήλαιο Αλιστράτης και στο ΚΠΕ Ποροΐων
A43: 46311 | B43: 09:50-10:55 | C43: Παγκόσμια Ημέρα Επανεκκίνησης Καρδιάς – «Kids Save Lives» | D43: Δράση / Πρόγραμμα / Όμιλος | E43: Ομάδες μαθητών από διάφορα τμήματα | F43: Βασιλακοπούλου, Κανοπούλου | H43: =IF($A43="","",CHOOSE(WEEKDAY($A43,2),"Δευ","Τρί","Τετ","Πέμ","Παρ","Σάβ","Κυρ")) | I43: =IF($A43="","",$A43&"#"&COUNTIF($A$2:$A43,$A43)) | J43: =IF($A43="","",IF($B43="","",$B43&" ")&$C43&IF($E43="",""," ("&$E43&")"))
H44: =IF($A44="","",CHOOSE(WEEKDAY($A44,2),"Δευ","Τρί","Τετ","Πέμ","Παρ","Σάβ","Κυρ")) | I44: =IF($A44="","",$A44&"#"&COUNTIF($A$2:$A44,$A44)) | J44: =IF($A44="","",IF($B44="","",$B44&" ")&$C44&IF($E44="",""," ("&$E44&")"))
H45: =IF($A45="","",CHOOSE(WEEKDAY($A45,2),"Δευ","Τρί","Τετ","Πέμ","Παρ","Σάβ","Κυρ")) | I45: =IF($A45="","",$A45&"#"&COUNTIF($A$2:$A45,$A45)) | J45: =IF($A45="","",IF($B45="","",$B45&" ")&$C45&IF($E45="",""," ("&$E45&")"))
...

Sheet ΑΦΙΣΑ_ΕΠΙΛΟΓΗΣ
A1: 3ο ΓΥΜΝΑΣΙΟ ΠΟΛΙΧΝΗΣ · ΗΜΕΡΟΛΟΓΙΟ ΔΡΑΣΕΩΝ · ΣΧΟΛΙΚΟ ΕΤΟΣ 2026-27 | K1: ΕΠΙΛΟΓΗ ΜΗΝΩΝ (βοηθητικά – δεν εκτυπώνονται) | N1: ΜΗΝΑΣ | O1: ΑΡ. | P1: ΕΤΟΣ+
A2: =$L$2&" "&$L$6 -> ΟΚΤΩΒΡΙΟΣ 2026 | F2: =$L$3&" "&$L$8 -> ΝΟΕΜΒΡΙΟΣ 2026 | K2: Μήνας αριστερά: | L2: ΟΚΤΩΒΡΙΟΣ | N2: ΣΕΠΤΕΜΒΡΙΟΣ | O2: 9 | P2: 0
A3: ΗΜΕΡΑ | B3: ΗΜ/ΝΙΑ | C3: ΚΑΤΗΓΟΡΙΑ | D3: ΔΡΑΣΕΙΣ ΤΗΣ ΗΜΕΡΑΣ | F3: ΗΜΕΡΑ | G3: ΗΜ/ΝΙΑ | H3: ΚΑΤΗΓΟΡΙΑ | I3: ΔΡΑΣΕΙΣ ΤΗΣ ΗΜΕΡΑΣ | K3: Μήνας δεξιά: | L3: ΝΟΕΜΒΡΙΟΣ | N3: ΟΚΤΩΒΡΙΟΣ | O3: 10 | P3: 0
A4: =IF($B4="","",CHOOSE(WEEKDAY($B4,2),"Δευ","Τρί","Τετ","Πέμ","Παρ","Σάβ","Κυρ")) -> Πέμ | B4: =IFERROR(IF(MONTH(DATE($L$6,$L$5,ROW()-3))=$L$5,DATE($L$6,$L$5,ROW()-3),""),"") -> 46296 | C4: =IFERROR(INDEX(ΔΡΑΣΕΙΣ!$D$2:$D$399,MATCH($B4&"#1",ΔΡΑΣΕΙΣ!$I$2:$I$399,0)),"") | D4: =IF($B4="","",IFERROR(INDEX(ΔΡΑΣΕΙΣ!$J$2:$J$399,MATCH($B4&"#1",ΔΡΑΣΕΙΣ!$I$2:$I$399,0)),"")&IFERROR(CHAR(10)&INDEX(ΔΡΑΣΕΙΣ!$J$2:$J$399,MATCH($B4&"#2",ΔΡΑΣΕΙΣ!$I$2:$I$399,0)),"")&IFERROR(CHAR(10)&INDEX(ΔΡΑΣΕΙΣ!$J$2:$J$399,MATCH($B4&"#3",ΔΡΑΣΕΙΣ!$I$2:$I$399,0)),"")) | F4: =IF($G4="","",CHOOSE(WEEKDAY($G4,2),"Δευ","Τρί","Τετ","Πέμ","Παρ","Σάβ","Κυρ")) -> Κυρ | G4: =IFERROR(IF(MONTH(DATE($L$8,$L$7,ROW()-3))=$L$7,DATE($L$8,$L$7,ROW()-3),""),"") -> 46327 | H4: =IFERROR(INDEX(ΔΡΑΣΕΙΣ!$D$2:$D$399,MATCH($G4&"#1",ΔΡΑΣΕΙΣ!$I$2:$I$399,0)),"") | I4: =IF($G4="","",IFERROR(INDEX(ΔΡΑΣΕΙΣ!$J$2:$J$399,MATCH($G4&"#1",ΔΡΑΣΕΙΣ!$I$2:$I$399,0)),"")&IFERROR(CHAR(10)&INDEX(ΔΡΑΣΕΙΣ!$J$2:$J$399,MATCH($G4&"#2",ΔΡΑΣΕΙΣ!$I$2:$I$399,0)),"")&IFERROR(CHAR(10)&INDEX(ΔΡΑΣΕΙΣ!$J$2:$J$399,MATCH($G4&"#3",ΔΡΑΣΕΙΣ!$I$2:$I$399,0)),"")) | N4: ΝΟΕΜΒΡΙΟΣ | O4: 11 | P4: 0
A5: =IF($B5="","",CHOOSE(WEEKDAY($B5,2),"Δευ","Τρί","Τετ","Πέμ","Παρ","Σάβ","Κυρ")) -> Παρ | B5: =IFERROR(IF(MONTH(DATE($L$6,$L$5,ROW()-3))=$L$5,DATE($L$6,$L$5,ROW()-3),""),"") -> 46297 | C5: =IFERROR(INDEX(ΔΡΑΣΕΙΣ!$D$2:$D$399,MATCH($B5&"#1",ΔΡΑΣΕΙΣ!$I$2:$I$399,0)),"") | D5: =IF($B5="","",IFERROR(INDEX(ΔΡΑΣΕΙΣ!$J$2:$J$399,MATCH($B5&"#1",ΔΡΑΣΕΙΣ!$I$2:$I$399,0)),"")&IFERROR(CHAR(10)&INDEX(ΔΡΑΣΕΙΣ!$J$2:$J$399,MATCH($B5&"#2",ΔΡΑΣΕΙΣ!$I$2:$I$399,0)),"")&IFERROR(CHAR(10)&INDEX(ΔΡΑΣΕΙΣ!$J$2:$J$399,MATCH($B5&"#3",ΔΡΑΣΕΙΣ!$I$2:$I$399,0)),"")) | F5: =IF($G5="","",CHOOSE(WEEKDAY($G5,2),"Δευ","Τρί","Τετ","Πέμ","Παρ","Σάβ","Κυρ")) -> Δευ | G5: =IFERROR(IF(MONTH(DATE($L$8,$L$7,ROW()-3))=$L$7,DATE($L$8,$L$7,ROW()-3),""),"") -> 46328 | H5: =IFERROR(INDEX(ΔΡΑΣΕΙΣ!$D$2:$D$399,MATCH($G5&"#1",ΔΡΑΣΕΙΣ!$I$2:$I$399,0)),"") | I5: =IF($G5="","",IFERROR(INDEX(ΔΡΑΣΕΙΣ!$J$2:$J$399,MATCH($G5&"#1",ΔΡΑΣΕΙΣ!$I$2:$I$399,0)),"")&IFERROR(CHAR(10)&INDEX(ΔΡΑΣΕΙΣ!$J$2:$J$399,MATCH($G5&"#2",ΔΡΑΣΕΙΣ!$I$2:$I$399,0)),"")&IFERROR(CHAR(10)&INDEX(ΔΡΑΣΕΙΣ!$J$2:$J$399,MATCH($G5&"#3",ΔΡΑΣΕΙΣ!$I$2:$I$399,0)),"")) | K5: αρ. μήνα Α | L5: =INDEX($O$2:$O$11,MATCH($L$2,$N$2:$N$11,0)) -> 10 | N5: ΔΕΚΕΜΒΡΙΟΣ | O5: 12 | P5: 0
A6: =IF($B6="","",CHOOSE(WEEKDAY($B6,2),"Δευ","Τρί","Τετ","Πέμ","Παρ","Σάβ","Κυρ")) -> Σάβ | B6: =IFERROR(IF(MONTH(DATE($L$6,$L$5,ROW()-3))=$L$5,DATE($L$6,$L$5,ROW()-3),""),"") -> 46298 | C6: =IFERROR(INDEX(ΔΡΑΣΕΙΣ!$D$2:$D$399,MATCH($B6&"#1",ΔΡΑΣΕΙΣ!$I$2:$I$399,0)),"") | D6: =IF($B6="","",IFERROR(INDEX(ΔΡΑΣΕΙΣ!$J$2:$J$399,MATCH($B6&"#1",ΔΡΑΣΕΙΣ!$I$2:$I$399,0)),"")&IFERROR(CHAR(10)&INDEX(ΔΡΑΣΕΙΣ!$J$2:$J$399,MATCH($B6&"#2",ΔΡΑΣΕΙΣ!$I$2:$I$399,0)),"")&IFERROR(CHAR(10)&INDEX(ΔΡΑΣΕΙΣ!$J$2:$J$399,MATCH($B6&"#3",ΔΡΑΣΕΙΣ!$I$2:$I$399,0)),"")) | F6: =IF($G6="","",CHOOSE(WEEKDAY($G6,2),"Δευ","Τρί","Τετ","Πέμ","Παρ","Σάβ","Κυρ")) -> Τρί | G6: =IFERROR(IF(MONTH(DATE($L$8,$L$7,ROW()-3))=$L$7,DATE($L$8,$L$7,ROW()-3),""),"") -> 46329 | H6: =IFERROR(INDEX(ΔΡΑΣΕΙΣ!$D$2:$D$399,MATCH($G6&"#1",ΔΡΑΣΕΙΣ!$I$2:$I$399,0)),"") | I6: =IF($G6="","",IFERROR(INDEX(ΔΡΑΣΕΙΣ!$J$2:$J$399,MATCH($G6&"#1",ΔΡΑΣΕΙΣ!$I$2:$I$399,0)),"")&IFERROR(CHAR(10)&INDEX(ΔΡΑΣΕΙΣ!$J$2:$J$399,MATCH($G6&"#2",ΔΡΑΣΕΙΣ!$I$2:$I$399,0)),"")&IFERROR(CHAR(10)&INDEX(ΔΡΑΣΕΙΣ!$J$2:$J$399,MATCH($G6&"#3",ΔΡΑΣΕΙΣ!$I$2:$I$399,0)),"")) | K6: έτος Α | L6: =ΟΔΗΓΙΕΣ!$B$3+INDEX($P$2:$P$11,MATCH($L$2,$N$2:$N$11,0)) -> 2026 | N6: ΙΑΝΟΥΑΡΙΟΣ | O6: 1 | P6: 1
A7: =IF($B7="","",CHOOSE(WEEKDAY($B7,2),"Δευ","Τρί","Τετ","Πέμ","Παρ","Σάβ","Κυρ")) -> Κυρ | B7: =IFERROR(IF(MONTH(DATE($L$6,$L$5,ROW()-3))=$L$5,DATE($L$6,$L$5,ROW()-3),""),"") -> 46299 | C7: =IFERROR(INDEX(ΔΡΑΣΕΙΣ!$D$2:$D$399,MATCH($B7&"#1",ΔΡΑΣΕΙΣ!$I$2:$I$399,0)),"") | D7: =IF($B7="","",IFERROR(INDEX(ΔΡΑΣΕΙΣ!$J$2:$J$399,MATCH($B7&"#1",ΔΡΑΣΕΙΣ!$I$2:$I$399,0)),"")&IFERROR(CHAR(10)&INDEX(ΔΡΑΣΕΙΣ!$J$2:$J$399,MATCH($B7&"#2",ΔΡΑΣΕΙΣ!$I$2:$I$399,0)),"")&IFERROR(CHAR(10)&INDEX(ΔΡΑΣΕΙΣ!$J$2:$J$399,MATCH($B7&"#3",ΔΡΑΣΕΙΣ!$I$2:$I$399,0)),"")) | F7: =IF($G7="","",CHOOSE(WEEKDAY($G7,2),"Δευ","Τρί","Τετ","Πέμ","Παρ","Σάβ","Κυρ")) -> Τετ | G7: =IFERROR(IF(MONTH(DATE($L$8,$L$7,ROW()-3))=$L$7,DATE($L$8,$L$7,ROW()-3),""),"") -> 46330 | H7: =IFERROR(INDEX(ΔΡΑΣΕΙΣ!$D$2:$D$399,MATCH($G7&"#1",ΔΡΑΣΕΙΣ!$I$2:$I$399,0)),"") -> Δράση / Πρόγραμμα / Όμιλος | I7: =IF($G7="","",IFERROR(INDEX(ΔΡΑΣΕΙΣ!$J$2:$J$399,MATCH($G7&"#1",ΔΡΑΣΕΙΣ!$I$2:$I$399,0)),"")&IFERROR(CHAR(10)&INDEX(ΔΡΑΣΕΙΣ!$J$2:$J$399,MATCH($G7&"#2",ΔΡΑΣΕΙΣ!$I$2:$I$399,0)),"")&IFERROR(CHAR(10)&INDEX(ΔΡΑΣΕΙΣ!$J$2:$J$399,MATCH($G7&"#3",ΔΡΑΣΕΙΣ!$I$2:$I$399,0)),"")) -> 08:45-11:15 Διαδικτυακή εκπαίδευση «Kids Save Lives» | K7: αρ. μήνα Β | L7: =INDEX($O$2:$O$11,MATCH($L$3,$N$2:$N$11,0)) -> 11 | N7: ΦΕΒΡΟΥΑΡΙΟΣ | O7: 2 | P7: 1
A8: =IF($B8="","",CHOOSE(WEEKDAY($B8,2),"Δευ","Τρί","Τετ","Πέμ","Παρ","Σάβ","Κυρ")) -> Δευ | B8: =IFERROR(IF(MONTH(DATE($L$6,$L$5,ROW()-3))=$L$5,DATE($L$6,$L$5,ROW()-3),""),"") -> 46300 | C8: =IFERROR(INDEX(ΔΡΑΣΕΙΣ!$D$2:$D$399,MATCH($B8&"#1",ΔΡΑΣΕΙΣ!$I$2:$I$399,0)),"") | D8: =IF($B8="","",IFERROR(INDEX(ΔΡΑΣΕΙΣ!$J$2:$J$399,MATCH($B8&"#1",ΔΡΑΣΕΙΣ!$I$2:$I$399,0)),"")&IFERROR(CHAR(10)&INDEX(ΔΡΑΣΕΙΣ!$J$2:$J$399,MATCH($B8&"#2",ΔΡΑΣΕΙΣ!$I$2:$I$399,0)),"")&IFERROR(CHAR(10)&INDEX(ΔΡΑΣΕΙΣ!$J$2:$J$399,MATCH($B8&"#3",ΔΡΑΣΕΙΣ!$I$2:$I$399,0)),"")) | F8: =IF($G8="","",CHOOSE(WEEKDAY($G8,2),"Δευ","Τρί","Τετ","Πέμ","Παρ","Σάβ","Κυρ")) -> Πέμ | G8: =IFERROR(IF(MONTH(DATE($L$8,$L$7,ROW()-3))=$L$7,DATE($L$8,$L$7,ROW()-3),""),"") -> 46331 | H8: =IFERROR(INDEX(ΔΡΑΣΕΙΣ!$D$2:$D$399,MATCH($G8&"#1",ΔΡΑΣΕΙΣ!$I$2:$I$399,0)),"") | I8: =IF($G8="","",IFERROR(INDEX(ΔΡΑΣΕΙΣ!$J$2:$J$399,MATCH($G8&"#1",ΔΡΑΣΕΙΣ!$I$2:$I$399,0)),"")&IFERROR(CHAR(10)&INDEX(ΔΡΑΣΕΙΣ!$J$2:$J$399,MATCH($G8&"#2",ΔΡΑΣΕΙΣ!$I$2:$I$399,0)),"")&IFERROR(CHAR(10)&INDEX(ΔΡΑΣΕΙΣ!$J$2:$J$399,MATCH($G8&"#3",ΔΡΑΣΕΙΣ!$I$2:$I$399,0)),"")) | K8: έτος Β | L8: =ΟΔΗΓΙΕΣ!$B$3+INDEX($P$2:$P$11,MATCH($L$3,$N$2:$N$11,0)) -> 2026 | N8: ΜΑΡΤΙΟΣ | O8: 3 | P8: 1
A9: =IF($B9="","",CHOOSE(WEEKDAY($B9,2),"Δευ","Τρί","Τετ","Πέμ","Παρ","Σάβ","Κυρ")) -> Τρί | B9: =IFERROR(IF(MONTH(DATE($L$6,$L$5,ROW()-3))=$L$5,DATE($L$6,$L$5,ROW()-3),""),"") -> 46301 | C9: =IFERROR(INDEX(ΔΡΑΣΕΙΣ!$D$2:$D$399,MATCH($B9&"#1",ΔΡΑΣΕΙΣ!$I$2:$I$399,0)),"") | D9: =IF($B9="","",IFERROR(INDEX(ΔΡΑΣΕΙΣ!$J$2:$J$399,MATCH($B9&"#1",ΔΡΑΣΕΙΣ!$I$2:$I$399,0)),"")&IFERROR(CHAR(10)&INDEX(ΔΡΑΣΕΙΣ!$J$2:$J$399,MATCH($B9&"#2",ΔΡΑΣΕΙΣ!$I$2:$I$399,0)),"")&IFERROR(CHAR(10)&INDEX(ΔΡΑΣΕΙΣ!$J$2:$J$399,MATCH($B9&"#3",ΔΡΑΣΕΙΣ!$I$2:$I$399,0)),"")) | F9: =IF($G9="","",CHOOSE(WEEKDAY($G9,2),"Δευ","Τρί","Τετ","Πέμ","Παρ","Σάβ","Κυρ")) -> Παρ | G9: =IFERROR(IF(MONTH(DATE($L$8,$L$7,ROW()-3))=$L$7,DATE($L$8,$L$7,ROW()-3),""),"") -> 46332 | H9: =IFERROR(INDEX(ΔΡΑΣΕΙΣ!$D$2:$D$399,MATCH($G9&"#1",ΔΡΑΣΕΙΣ!$I$2:$I$399,0)),"") | I9: =IF($G9="","",IFERROR(INDEX(ΔΡΑΣΕΙΣ!$J$2:$J$399,MATCH($G9&"#1",ΔΡΑΣΕΙΣ!$I$2:$I$399,0)),"")&IFERROR(CHAR(10)&INDEX(ΔΡΑΣΕΙΣ!$J$2:$J$399,MATCH($G9&"#2",ΔΡΑΣΕΙΣ!$I$2:$I$399,0)),"")&IFERROR(CHAR(10)&INDEX(ΔΡΑΣΕΙΣ!$J$2:$J$399,MATCH($G9&"#3",ΔΡΑΣΕΙΣ!$I$2:$I$399,0)),"")) | N9: ΑΠΡΙΛΙΟΣ | O9: 4 | P9: 1
A10: =IF($B10="","",CHOOSE(WEEKDAY($B10,2),"Δευ","Τρί","Τετ","Πέμ","Παρ","Σάβ","Κυρ")) -> Τετ | B10: =IFERROR(IF(MONTH(DATE($L$6,$L$5,ROW()-3))=$L$5,DATE($L$6,$L$5,ROW()-3),""),"") -> 46302 | C10: =IFERROR(INDEX(ΔΡΑΣΕΙΣ!$D$2:$D$399,MATCH($B10&"#1",ΔΡΑΣΕΙΣ!$I$2:$I$399,0)),"") | D10: =IF($B10="","",IFERROR(INDEX(ΔΡΑΣΕΙΣ!$J$2:$J$399,MATCH($B10&"#1",ΔΡΑΣΕΙΣ!$I$2:$I$399,0)),"")&IFERROR(CHAR(10)&INDEX(ΔΡΑΣΕΙΣ!$J$2:$J$399,MATCH($B10&"#2",ΔΡΑΣΕΙΣ!$I$2:$I$399,0)),"")&IFERROR(CHAR(10)&INDEX(ΔΡΑΣΕΙΣ!$J$2:$J$399,MATCH($B10&"#3",ΔΡΑΣΕΙΣ!$I$2:$I$399,0)),"")) | F10: =IF($G10="","",CHOOSE(WEEKDAY($G10,2),"Δευ","Τρί","Τετ","Πέμ","Παρ","Σάβ","Κυρ")) -> Σάβ | G10: =IFERROR(IF(MONTH(DATE($L$8,$L$7,ROW()-3))=$L$7,DATE($L$8,$L$7,ROW()-3),""),"") -> 46333 | H10: =IFERROR(INDEX(ΔΡΑΣΕΙΣ!$D$2:$D$399,MATCH($G10&"#1",ΔΡΑΣΕΙΣ!$I$2:$I$399,0)),"") | I10: =IF($G10="","",IFERROR(INDEX(ΔΡΑΣΕΙΣ!$J$2:$J$399,MATCH($G10&"#1",ΔΡΑΣΕΙΣ!$I$2:$I$399,0)),"")&IFERROR(CHAR(10)&INDEX(ΔΡΑΣΕΙΣ!$J$2:$J$399,MATCH($G10&"#2",ΔΡΑΣΕΙΣ!$I$2:$I$399,0)),"")&IFERROR(CHAR(10)&INDEX(ΔΡΑΣΕΙΣ!$J$2:$J$399,MATCH($G10&"#3",ΔΡΑΣΕΙΣ!$I$2:$I$399,0)),"")) | N10: ΜΑΪΟΣ | O10: 5 | P10: 1
A11: =IF($B11="","",CHOOSE(WEEKDAY($B11,2),"Δευ","Τρί","Τετ","Πέμ","Παρ","Σάβ","Κυρ")) -> Πέμ | B11: =IFERROR(IF(MONTH(DATE($L$6,$L$5,ROW()-3))=$L$5,DATE($L$6,$L$5,ROW()-3),""),"") -> 46303 | C11: =IFERROR(INDEX(ΔΡΑΣΕΙΣ!$D$2:$D$399,MATCH($B11&"#1",ΔΡΑΣΕΙΣ!$I$2:$I$399,0)),"") | D11: =IF($B11="","",IFERROR(INDEX(ΔΡΑΣΕΙΣ!$J$2:$J$399,MATCH($B11&"#1",ΔΡΑΣΕΙΣ!$I$2:$I$399,0)),"")&IFERROR(CHAR(10)&INDEX(ΔΡΑΣΕΙΣ!$J$2:$J$399,MATCH($B11&"#2",ΔΡΑΣΕΙΣ!$I$2:$I$399,0)),"")&IFERROR(CHAR(10)&INDEX(ΔΡΑΣΕΙΣ!$J$2:$J$399,MATCH($B11&"#3",ΔΡΑΣΕΙΣ!$I$2:$I$399,0)),"")) | F11: =IF($G11="","",CHOOSE(WEEKDAY($G11,2),"Δευ","Τρί","Τετ","Πέμ","Παρ","Σάβ","Κυρ")) -> Κυρ | G11: =IFERROR(IF(MONTH(DATE($L$8,$L$7,ROW()-3))=$L$7,DATE($L$8,$L$7,ROW()-3),""),"") -> 46334 | H11: =IFERROR(INDEX(ΔΡΑΣΕΙΣ!$D$2:$D$399,MATCH($G11&"#1",ΔΡΑΣΕΙΣ!$I$2:$I$399,0)),"") | I11: =IF($G11="","",IFERROR(INDEX(ΔΡΑΣΕΙΣ!$J$2:$J$399,MATCH($G11&"#1",ΔΡΑΣΕΙΣ!$I$2:$I$399,0)),"")&IFERROR(CHAR(10)&INDEX(ΔΡΑΣΕΙΣ!$J$2:$J$399,MATCH($G11&"#2",ΔΡΑΣΕΙΣ!$I$2:$I$399,0)),"")&IFERROR(CHAR(10)&INDEX(ΔΡΑΣΕΙΣ!$J$2:$J$399,MATCH($G11&"#3",ΔΡΑΣΕΙΣ!$I$2:$I$399,0)),"")) | N11: ΙΟΥΝΙΟΣ | O11: 6 | P11: 1
A12: =IF($B12="","",CHOOSE(WEEKDAY($B12,2),"Δευ","Τρί","Τετ","Πέμ","Παρ","Σάβ","Κυρ")) -> Παρ | B12: =IFERROR(IF(MONTH(DATE($L$6,$L$5,ROW()-3))=$L$5,DATE($L$6,$L$5,ROW()-3),""),"") -> 46304 | C12: =IFERROR(INDEX(ΔΡΑΣΕΙΣ!$D$2:$D$399,MATCH($B12&"#1",ΔΡΑΣΕΙΣ!$I$2:$I$399,0)),"") | D12: =IF($B12="","",IFERROR(INDEX(ΔΡΑΣΕΙΣ!$J$2:$J$399,MATCH($B12&"#1",ΔΡΑΣΕΙΣ!$I$2:$I$399,0)),"")&IFERROR(CHAR(10)&INDEX(ΔΡΑΣΕΙΣ!$J$2:$J$399,MATCH($B12&"#2",ΔΡΑΣΕΙΣ!$I$2:$I$399,0)),"")&IFERROR(CHAR(10)&INDEX(ΔΡΑΣΕΙΣ!$J$2:$J$399,MATCH($B12&"#3",ΔΡΑΣΕΙΣ!$I$2:$I$399,0)),"")) | F12: =IF($G12="","",CHOOSE(WEEKDAY($G12,2),"Δευ","Τρί","Τετ","Πέμ","Παρ","Σάβ","Κυρ")) -> Δευ | G12: =IFERROR(IF(MONTH(DATE($L$8,$L$7,ROW()-3))=$L$7,DATE($L$8,$L$7,ROW()-3),""),"") -> 46335 | H12: =IFERROR(INDEX(ΔΡΑΣΕΙΣ!$D$2:$D$399,MATCH($G12&"#1",ΔΡΑΣΕΙΣ!$I$2:$I$399,0)),"") | I12: =IF($G12="","",IFERROR(INDEX(ΔΡΑΣΕΙΣ!$J$2:$J$399,MATCH($G12&"#1",ΔΡΑΣΕΙΣ!$I$2:$I$399,0)),"")&IFERROR(CHAR(10)&INDEX(ΔΡΑΣΕΙΣ!$J$2:$J$399,MATCH($G12&"#2",ΔΡΑΣΕΙΣ!$I$2:$I$399,0)),"")&IFERROR(CHAR(10)&INDEX(ΔΡΑΣΕΙΣ!$J$2:$J$399,MATCH($G12&"#3",ΔΡΑΣΕΙΣ!$I$2:$I$399,0)),""))
A13: =IF($B13="","",CHOOSE(WEEKDAY($B13,2),"Δευ","Τρί","Τετ","Πέμ","Παρ","Σάβ","Κυρ")) -> Σάβ | B13: =IFERROR(IF(MONTH(DATE($L$6,$L$5,ROW()-3))=$L$5,DATE($L$6,$L$5,ROW()-3),""),"") -> 46305 | C13: =IFERROR(INDEX(ΔΡΑΣΕΙΣ!$D$2:$D$399,MATCH($B13&"#1",ΔΡΑΣΕΙΣ!$I$2:$I$399,0)),"") | D13: =IF($B13="","",IFERROR(INDEX(ΔΡΑΣΕΙΣ!$J$2:$J$399,MATCH($B13&"#1",ΔΡΑΣΕΙΣ!$I$2:$I$399,0)),"")&IFERROR(CHAR(10)&INDEX(ΔΡΑΣΕΙΣ!$J$2:$J$399,MATCH($B13&"#2",ΔΡΑΣΕΙΣ!$I$2:$I$399,0)),"")&IFERROR(CHAR(10)&INDEX(ΔΡΑΣΕΙΣ!$J$2:$J$399,MATCH($B13&"#3",ΔΡΑΣΕΙΣ!$I$2:$I$399,0)),"")) | F13: =IF($G13="","",CHOOSE(WEEKDAY($G13,2),"Δευ","Τρί","Τετ","Πέμ","Παρ","Σάβ","Κυρ")) -> Τρί | G13: =IFERROR(IF(MONTH(DATE($L$8,$L$7,ROW()-3))=$L$7,DATE($L$8,$L$7,ROW()-3),""),"") -> 46336 | H13: =IFERROR(INDEX(ΔΡΑΣΕΙΣ!$D$2:$D$399,MATCH($G13&"#1",ΔΡΑΣΕΙΣ!$I$2:$I$399,0)),"") | I13: =IF($G13="","",IFERROR(INDEX(ΔΡΑΣΕΙΣ!$J$2:$J$399,MATCH($G13&"#1",ΔΡΑΣΕΙΣ!$I$2:$I$399,0)),"")&IFERROR(CHAR(10)&INDEX(ΔΡΑΣΕΙΣ!$J$2:$J$399,MATCH($G13&"#2",ΔΡΑΣΕΙΣ!$I$2:$I$399,0)),"")&IFERROR(CHAR(10)&INDEX(ΔΡΑΣΕΙΣ!$J$2:$J$399,MATCH($G13&"#3",ΔΡΑΣΕΙΣ!$I$2:$I$399,0)),""))
A14: =IF($B14="","",CHOOSE(WEEKDAY($B14,2),"Δευ","Τρί","Τετ","Πέμ","Παρ","Σάβ","Κυρ")) -> Κυρ | B14: =IFERROR(IF(MONTH(DATE($L$6,$L$5,ROW()-3))=$L$5,DATE($L$6,$L$5,ROW()-3),""),"") -> 46306 | C14: =IFERROR(INDEX(ΔΡΑΣΕΙΣ!$D$2:$D$399,MATCH($B14&"#1",ΔΡΑΣΕΙΣ!$I$2:$I$399,0)),"") | D14: =IF($B14="","",IFERROR(INDEX(ΔΡΑΣΕΙΣ!$J$2:$J$399,MATCH($B14&"#1",ΔΡΑΣΕΙΣ!$I$2:$I$399,0)),"")&IFERROR(CHAR(10)&INDEX(ΔΡΑΣΕΙΣ!$J$2:$J$399,MATCH($B14&"#2",ΔΡΑΣΕΙΣ!$I$2:$I$399,0)),"")&IFERROR(CHAR(10)&INDEX(ΔΡΑΣΕΙΣ!$J$2:$J$399,MATCH($B14&"#3",ΔΡΑΣΕΙΣ!$I$2:$I$399,0)),"")) | F14: =IF($G14="","",CHOOSE(WEEKDAY($G14,2),"Δευ","Τρί","Τετ","Πέμ","Παρ","Σάβ","Κυρ")) -> Τετ | G14: =IFERROR(IF(MONTH(DATE($L$8,$L$7,ROW()-3))=$L$7,DATE($L$8,$L$7,ROW()-3),""),"") -> 46337 | H14: =IFERROR(INDEX(ΔΡΑΣΕΙΣ!$D$2:$D$399,MATCH($G14&"#1",ΔΡΑΣΕΙΣ!$I$2:$I$399,0)),"") | I14: =IF($G14="","",IFERROR(INDEX(ΔΡΑΣΕΙΣ!$J$2:$J$399,MATCH($G14&"#1",ΔΡΑΣΕΙΣ!$I$2:$I$399,0)),"")&IFERROR(CHAR(10)&INDEX(ΔΡΑΣΕΙΣ!$J$2:$J$399,MATCH($G14&"#2",ΔΡΑΣΕΙΣ!$I$2:$I$399,0)),"")&IFERROR(CHAR(10)&INDEX(ΔΡΑΣΕΙΣ!$J$2:$J$399,MATCH($G14&"#3",ΔΡΑΣΕΙΣ!$I$2:$I$399,0)),""))
A15: =IF($B15="","",CHOOSE(WEEKDAY($B15,2),"Δευ","Τρί","Τετ","Πέμ","Παρ","Σάβ","Κυρ")) -> Δευ | B15: =IFERROR(IF(MONTH(DATE($L$6,$L$5,ROW()-3))=$L$5,DATE($L$6,$L$5,ROW()-3),""),"") -> 46307 | C15: =IFERROR(INDEX(ΔΡΑΣΕΙΣ!$D$2:$D$399,MATCH($B15&"#1",ΔΡΑΣΕΙΣ!$I$2:$I$399,0)),"") | D15: =IF($B15="","",IFERROR(INDEX(ΔΡΑΣΕΙΣ!$J$2:$J$399,MATCH($B15&"#1",ΔΡΑΣΕΙΣ!$I$2:$I$399,0)),"")&IFERROR(CHAR(10)&INDEX(ΔΡΑΣΕΙΣ!$J$2:$J$399,MATCH($B15&"#2",ΔΡΑΣΕΙΣ!$I$2:$I$399,0)),"")&IFERROR(CHAR(10)&INDEX(ΔΡΑΣΕΙΣ!$J$2:$J$399,MATCH($B15&"#3",ΔΡΑΣΕΙΣ!$I$2:$I$399,0)),"")) | F15: =IF($G15="","",CHOOSE(WEEKDAY($G15,2),"Δευ","Τρί","Τετ","Πέμ","Παρ","Σάβ","Κυρ")) -> Πέμ | G15: =IFERROR(IF(MONTH(DATE($L$8,$L$7,ROW()-3))=$L$7,DATE($L$8,$L$7,ROW()-3),""),"") -> 46338 | H15: =IFERROR(INDEX(ΔΡΑΣΕΙΣ!$D$2:$D$399,MATCH($G15&"#1",ΔΡΑΣΕΙΣ!$I$2:$I$399,0)),"") | I15: =IF($G15="","",IFERROR(INDEX(ΔΡΑΣΕΙΣ!$J$2:$J$399,MATCH($G15&"#1",ΔΡΑΣΕΙΣ!$I$2:$I$399,0)),"")&IFERROR(CHAR(10)&INDEX(ΔΡΑΣΕΙΣ!$J$2:$J$399,MATCH($G15&"#2",ΔΡΑΣΕΙΣ!$I$2:$I$399,0)),"")&IFERROR(CHAR(10)&INDEX(ΔΡΑΣΕΙΣ!$J$2:$J$399,MATCH($G15&"#3",ΔΡΑΣΕΙΣ!$I$2:$I$399,0)),""))
A16: =IF($B16="","",CHOOSE(WEEKDAY($B16,2),"Δευ","Τρί","Τετ","Πέμ","Παρ","Σάβ","Κυρ")) -> Τρί | B16: =IFERROR(IF(MONTH(DATE($L$6,$L$5,ROW()-3))=$L$5,DATE($L$6,$L$5,ROW()-3),""),"") -> 46308 | C16: =IFERROR(INDEX(ΔΡΑΣΕΙΣ!$D$2:$D$399,MATCH($B16&"#1",ΔΡΑΣΕΙΣ!$I$2:$I$399,0)),"") | D16: =IF($B16="","",IFERROR(INDEX(ΔΡΑΣΕΙΣ!$J$2:$J$399,MATCH($B16&"#1",ΔΡΑΣΕΙΣ!$I$2:$I$399,0)),"")&IFERROR(CHAR(10)&INDEX(ΔΡΑΣΕΙΣ!$J$2:$J$399,MATCH($B16&"#2",ΔΡΑΣΕΙΣ!$I$2:$I$399,0)),"")&IFERROR(CHAR(10)&INDEX(ΔΡΑΣΕΙΣ!$J$2:$J$399,MATCH($B16&"#3",ΔΡΑΣΕΙΣ!$I$2:$I$399,0)),"")) | F16: =IF($G16="","",CHOOSE(WEEKDAY($G16,2),"Δευ","Τρί","Τετ","Πέμ","Παρ","Σάβ","Κυρ")) -> Παρ | G16: =IFERROR(IF(MONTH(DATE($L$8,$L$7,ROW()-3))=$L$7,DATE($L$8,$L$7,ROW()-3),""),"") -> 46339 | H16: =IFERROR(INDEX(ΔΡΑΣΕΙΣ!$D$2:$D$399,MATCH($G16&"#1",ΔΡΑΣΕΙΣ!$I$2:$I$399,0)),"") | I16: =IF($G16="","",IFERROR(INDEX(ΔΡΑΣΕΙΣ!$J$2:$J$399,MATCH($G16&"#1",ΔΡΑΣΕΙΣ!$I$2:$I$399,0)),"")&IFERROR(CHAR(10)&INDEX(ΔΡΑΣΕΙΣ!$J$2:$J$399,MATCH($G16&"#2",ΔΡΑΣΕΙΣ!$I$2:$I$399,0)),"")&IFERROR(CHAR(10)&INDEX(ΔΡΑΣΕΙΣ!$J$2:$J$399,MATCH($G16&"#3",ΔΡΑΣΕΙΣ!$I$2:$I$399,0)),""))
A17: =IF($B17="","",CHOOSE(WEEKDAY($B17,2),"Δευ","Τρί","Τετ","Πέμ","Παρ","Σάβ","Κυρ")) -> Τετ | B17: =IFERROR(IF(MONTH(DATE($L$6,$L$5,ROW()-3))=$L$5,DATE($L$6,$L$5,ROW()-3),""),"") -> 46309 | C17: =IFERROR(INDEX(ΔΡΑΣΕΙΣ!$D$2:$D$399,MATCH($B17&"#1",ΔΡΑΣΕΙΣ!$I$2:$I$399,0)),"") | D17: =IF($B17="","",IFERROR(INDEX(ΔΡΑΣΕΙΣ!$J$2:$J$399,MATCH($B17&"#1",ΔΡΑΣΕΙΣ!$I$2:$I$399,0)),"")&IFERROR(CHAR(10)&INDEX(ΔΡΑΣΕΙΣ!$J$2:$J$399,MATCH($B17&"#2",ΔΡΑΣΕΙΣ!$I$2:$I$399,0)),"")&IFERROR(CHAR(10)&INDEX(ΔΡΑΣΕΙΣ!$J$2:$J$399,MATCH($B17&"#3",ΔΡΑΣΕΙΣ!$I$2:$I$399,0)),"")) | F17: =IF($G17="","",CHOOSE(WEEKDAY($G17,2),"Δευ","Τρί","Τετ","Πέμ","Παρ","Σάβ","Κυρ")) -> Σάβ | G17: =IFERROR(IF(MONTH(DATE($L$8,$L$7,ROW()-3))=$L$7,DATE($L$8,$L$7,ROW()-3),""),"") -> 46340 | H17: =IFERROR(INDEX(ΔΡΑΣΕΙΣ!$D$2:$D$399,MATCH($G17&"#1",ΔΡΑΣΕΙΣ!$I$2:$I$399,0)),"") | I17: =IF($G17="","",IFERROR(INDEX(ΔΡΑΣΕΙΣ!$J$2:$J$399,MATCH($G17&"#1",ΔΡΑΣΕΙΣ!$I$2:$I$399,0)),"")&IFERROR(CHAR(10)&INDEX(ΔΡΑΣΕΙΣ!$J$2:$J$399,MATCH($G17&"#2",ΔΡΑΣΕΙΣ!$I$2:$I$399,0)),"")&IFERROR(CHAR(10)&INDEX(ΔΡΑΣΕΙΣ!$J$2:$J$399,MATCH($G17&"#3",ΔΡΑΣΕΙΣ!$I$2:$I$399,0)),""))
A18: =IF($B18="","",CHOOSE(WEEKDAY($B18,2),"Δευ","Τρί","Τετ","Πέμ","Παρ","Σάβ","Κυρ")) -> Πέμ | B18: =IFERROR(IF(MONTH(DATE($L$6,$L$5,ROW()-3))=$L$5,DATE($L$6,$L$5,ROW()-3),""),"") -> 46310 | C18: =IFERROR(INDEX(ΔΡΑΣΕΙΣ!$D$2:$D$399,MATCH($B18&"#1",ΔΡΑΣΕΙΣ!$I$2:$I$399,0)),"") | D18: =IF($B18="","",IFERROR(INDEX(ΔΡΑΣΕΙΣ!$J$2:$J$399,MATCH($B18&"#1",ΔΡΑΣΕΙΣ!$I$2:$I$399,0)),"")&IFERROR(CHAR(10)&INDEX(ΔΡΑΣΕΙΣ!$J$2:$J$399,MATCH($B18&"#2",ΔΡΑΣΕΙΣ!$I$2:$I$399,0)),"")&IFERROR(CHAR(10)&INDEX(ΔΡΑΣΕΙΣ!$J$2:$J$399,MATCH($B18&"#3",ΔΡΑΣΕΙΣ!$I$2:$I$399,0)),"")) | F18: =IF($G18="","",CHOOSE(WEEKDAY($G18,2),"Δευ","Τρί","Τετ","Πέμ","Παρ","Σάβ","Κυρ")) -> Κυρ | G18: =IFERROR(IF(MONTH(DATE($L$8,$L$7,ROW()-3))=$L$7,DATE($L$8,$L$7,ROW()-3),""),"") -> 46341 | H18: =IFERROR(INDEX(ΔΡΑΣΕΙΣ!$D$2:$D$399,MATCH($G18&"#1",ΔΡΑΣΕΙΣ!$I$2:$I$399,0)),"") | I18: =IF($G18="","",IFERROR(INDEX(ΔΡΑΣΕΙΣ!$J$2:$J$399,MATCH($G18&"#1",ΔΡΑΣΕΙΣ!$I$2:$I$399,0)),"")&IFERROR(CHAR(10)&INDEX(ΔΡΑΣΕΙΣ!$J$2:$J$399,MATCH($G18&"#2",ΔΡΑΣΕΙΣ!$I$2:$I$399,0)),"")&IFERROR(CHAR(10)&INDEX(ΔΡΑΣΕΙΣ!$J$2:$J$399,MATCH($G18&"#3",ΔΡΑΣΕΙΣ!$I$2:$I$399,0)),""))
A19: =IF($B19="","",CHOOSE(WEEKDAY($B19,2),"Δευ","Τρί","Τετ","Πέμ","Παρ","Σάβ","Κυρ")) -> Παρ | B19: =IFERROR(IF(MONTH(DATE($L$6,$L$5,ROW()-3))=$L$5,DATE($L$6,$L$5,ROW()-3),""),"") -> 46311 | C19: =IFERROR(INDEX(ΔΡΑΣΕΙΣ!$D$2:$D$399,MATCH($B19&"#1",ΔΡΑΣΕΙΣ!$I$2:$I$399,0)),"") | D19: =IF($B19="","",IFERROR(INDEX(ΔΡΑΣΕΙΣ!$J$2:$J$399,MATCH($B19&"#1",ΔΡΑΣΕΙΣ!$I$2:$I$399,0)),"")&IFERROR(CHAR(10)&INDEX(ΔΡΑΣΕΙΣ!$J$2:$J$399,MATCH($B19&"#2",ΔΡΑΣΕΙΣ!$I$2:$I$399,0)),"")&IFERROR(CHAR(10)&INDEX(ΔΡΑΣΕΙΣ!$J$2:$J$399,MATCH($B19&"#3",ΔΡΑΣΕΙΣ!$I$2:$I$399,0)),"")) | F19: =IF($G19="","",CHOOSE(WEEKDAY($G19,2),"Δευ","Τρί","Τετ","Πέμ","Παρ","Σάβ","Κυρ")) -> Δευ | G19: =IFERROR(IF(MONTH(DATE($L$8,$L$7,ROW()-3))=$L$7,DATE($L$8,$L$7,ROW()-3),""),"") -> 46342 | H19: =IFERROR(INDEX(ΔΡΑΣΕΙΣ!$D$2:$D$399,MATCH($G19&"#1",ΔΡΑΣΕΙΣ!$I$2:$I$399,0)),"") | I19: =IF($G19="","",IFERROR(INDEX(ΔΡΑΣΕΙΣ!$J$2:$J$399,MATCH($G19&"#1",ΔΡΑΣΕΙΣ!$I$2:$I$399,0)),"")&IFERROR(CHAR(10)&INDEX(ΔΡΑΣΕΙΣ!$J$2:$J$399,MATCH($G19&"#2",ΔΡΑΣΕΙΣ!$I$2:$I$399,0)),"")&IFERROR(CHAR(10)&INDEX(ΔΡΑΣΕΙΣ!$J$2:$J$399,MATCH($G19&"#3",ΔΡΑΣΕΙΣ!$I$2:$I$399,0)),""))
A20: =IF($B20="","",CHOOSE(WEEKDAY($B20,2),"Δευ","Τρί","Τετ","Πέμ","Παρ","Σάβ","Κυρ")) -> Σάβ | B20: =IFERROR(IF(MONTH(DATE($L$6,$L$5,ROW()-3))=$L$5,DATE($L$6,$L$5,ROW()-3),""),"") -> 46312 | C20: =IFERROR(INDEX(ΔΡΑΣΕΙΣ!$D$2:$D$399,MATCH($B20&"#1",ΔΡΑΣΕΙΣ!$I$2:$I$399,0)),"") | D20: =IF($B20="","",IFERROR(INDEX(ΔΡΑΣΕΙΣ!$J$2:$J$399,MATCH($B20&"#1",ΔΡΑΣΕΙΣ!$I$2:$I$399,0)),"")&IFERROR(CHAR(10)&INDEX(ΔΡΑΣΕΙΣ!$J$2:$J$399,MATCH($B20&"#2",ΔΡΑΣΕΙΣ!$I$2:$I$399,0)),"")&IFERROR(CHAR(10)&INDEX(ΔΡΑΣΕΙΣ!$J$2:$J$399,MATCH($B20&"#3",ΔΡΑΣΕΙΣ!$I$2:$I$399,0)),"")) | F20: =IF($G20="","",CHOOSE(WEEKDAY($G20,2),"Δευ","Τρί","Τετ","Πέμ","Παρ","Σάβ","Κυρ")) -> Τρί | G20: =IFERROR(IF(MONTH(DATE($L$8,$L$7,ROW()-3))=$L$7,DATE($L$8,$L$7,ROW()-3),""),"") -> 46343 | H20: =IFERROR(INDEX(ΔΡΑΣΕΙΣ!$D$2:$D$399,MATCH($G20&"#1",ΔΡΑΣΕΙΣ!$I$2:$I$399,0)),"") -> Εορτή / Εκκλησιασμός | I20: =IF($G20="","",IFERROR(INDEX(ΔΡΑΣΕΙΣ!$J$2:$J$399,MATCH($G20&"#1",ΔΡΑΣΕΙΣ!$I$2:$I$399,0)),"")&IFERROR(CHAR(10)&INDEX(ΔΡΑΣΕΙΣ!$J$2:$J$399,MATCH($G20&"#2",ΔΡΑΣΕΙΣ!$I$2:$I$399,0)),"")&IFERROR(CHAR(10)&INDEX(ΔΡΑΣΕΙΣ!$J$2:$J$399,MATCH($G20&"#3",ΔΡΑΣΕΙΣ!$I$2:$I$399,0)),"")) -> Εκδηλώσεις για την επέτειο του Πολυτεχνείου
A21: =IF($B21="","",CHOOSE(WEEKDAY($B21,2),"Δευ","Τρί","Τετ","Πέμ","Παρ","Σάβ","Κυρ")) -> Κυρ | B21: =IFERROR(IF(MONTH(DATE($L$6,$L$5,ROW()-3))=$L$5,DATE($L$6,$L$5,ROW()-3),""),"") -> 46313 | C21: =IFERROR(INDEX(ΔΡΑΣΕΙΣ!$D$2:$D$399,MATCH($B21&"#1",ΔΡΑΣΕΙΣ!$I$2:$I$399,0)),"") | D21: =IF($B21="","",IFERROR(INDEX(ΔΡΑΣΕΙΣ!$J$2:$J$399,MATCH($B21&"#1",ΔΡΑΣΕΙΣ!$I$2:$I$399,0)),"")&IFERROR(CHAR(10)&INDEX(ΔΡΑΣΕΙΣ!$J$2:$J$399,MATCH($B21&"#2",ΔΡΑΣΕΙΣ!$I$2:$I$399,0)),"")&IFERROR(CHAR(10)&INDEX(ΔΡΑΣΕΙΣ!$J$2:$J$399,MATCH($B21&"#3",ΔΡΑΣΕΙΣ!$I$2:$I$399,0)),"")) | F21: =IF($G21="","",CHOOSE(WEEKDAY($G21,2),"Δευ","Τρί","Τετ","Πέμ","Παρ","Σάβ","Κυρ")) -> Τετ | G21: =IFERROR(IF(MONTH(DATE($L$8,$L$7,ROW()-3))=$L$7,DATE($L$8,$L$7,ROW()-3),""),"") -> 46344 | H21: =IFERROR(INDEX(ΔΡΑΣΕΙΣ!$D$2:$D$399,MATCH($G21&"#1",ΔΡΑΣΕΙΣ!$I$2:$I$399,0)),"") | I21: =IF($G21="","",IFERROR(INDEX(ΔΡΑΣΕΙΣ!$J$2:$J$399,MATCH($G21&"#1",ΔΡΑΣΕΙΣ!$I$2:$I$399,0)),"")&IFERROR(CHAR(10)&INDEX(ΔΡΑΣΕΙΣ!$J$2:$J$399,MATCH($G21&"#2",ΔΡΑΣΕΙΣ!$I$2:$I$399,0)),"")&IFERROR(CHAR(10)&INDEX(ΔΡΑΣΕΙΣ!$J$2:$J$399,MATCH($G21&"#3",ΔΡΑΣΕΙΣ!$I$2:$I$399,0)),""))
A22: =IF($B22="","",CHOOSE(WEEKDAY($B22,2),"Δευ","Τρί","Τετ","Πέμ","Παρ","Σάβ","Κυρ")) -> Δευ | B22: =IFERROR(IF(MONTH(DATE($L$6,$L$5,ROW()-3))=$L$5,DATE($L$6,$L$5,ROW()-3),""),"") -> 46314 | C22: =IFERROR(INDEX(ΔΡΑΣΕΙΣ!$D$2:$D$399,MATCH($B22&"#1",ΔΡΑΣΕΙΣ!$I$2:$I$399,0)),"") | D22: =IF($B22="","",IFERROR(INDEX(ΔΡΑΣΕΙΣ!$J$2:$J$399,MATCH($B22&"#1",ΔΡΑΣΕΙΣ!$I$2:$I$399,0)),"")&IFERROR(CHAR(10)&INDEX(ΔΡΑΣΕΙΣ!$J$2:$J$399,MATCH($B22&"#2",ΔΡΑΣΕΙΣ!$I$2:$I$399,0)),"")&IFERROR(CHAR(10)&INDEX(ΔΡΑΣΕΙΣ!$J$2:$J$399,MATCH($B22&"#3",ΔΡΑΣΕΙΣ!$I$2:$I$399,0)),"")) | F22: =IF($G22="","",CHOOSE(WEEKDAY($G22,2),"Δευ","Τρί","Τετ","Πέμ","Παρ","Σάβ","Κυρ")) -> Πέμ | G22: =IFERROR(IF(MONTH(DATE($L$8,$L$7,ROW()-3))=$L$7,DATE($L$8,$L$7,ROW()-3),""),"") -> 46345 | H22: =IFERROR(INDEX(ΔΡΑΣΕΙΣ!$D$2:$D$399,MATCH($G22&"#1",ΔΡΑΣΕΙΣ!$I$2:$I$399,0)),"") | I22: =IF($G22="","",IFERROR(INDEX(ΔΡΑΣΕΙΣ!$J$2:$J$399,MATCH($G22&"#1",ΔΡΑΣΕΙΣ!$I$2:$I$399,0)),"")&IFERROR(CHAR(10)&INDEX(ΔΡΑΣΕΙΣ!$J$2:$J$399,MATCH($G22&"#2",ΔΡΑΣΕΙΣ!$I$2:$I$399,0)),"")&IFERROR(CHAR(10)&INDEX(ΔΡΑΣΕΙΣ!$J$2:$J$399,MATCH($G22&"#3",ΔΡΑΣΕΙΣ!$I$2:$I$399,0)),""))
A23: =IF($B23="","",CHOOSE(WEEKDAY($B23,2),"Δευ","Τρί","Τετ","Πέμ","Παρ","Σάβ","Κυρ")) -> Τρί | B23: =IFERROR(IF(MONTH(DATE($L$6,$L$5,ROW()-3))=$L$5,DATE($L$6,$L$5,ROW()-3),""),"") -> 46315 | C23: =IFERROR(INDEX(ΔΡΑΣΕΙΣ!$D$2:$D$399,MATCH($B23&"#1",ΔΡΑΣΕΙΣ!$I$2:$I$399,0)),"") | D23: =IF($B23="","",IFERROR(INDEX(ΔΡΑΣΕΙΣ!$J$2:$J$399,MATCH($B23&"#1",ΔΡΑΣΕΙΣ!$I$2:$I$399,0)),"")&IFERROR(CHAR(10)&INDEX(ΔΡΑΣΕΙΣ!$J$2:$J$399,MATCH($B23&"#2",ΔΡΑΣΕΙΣ!$I$2:$I$399,0)),"")&IFERROR(CHAR(10)&INDEX(ΔΡΑΣΕΙΣ!$J$2:$J$399,MATCH($B23&"#3",ΔΡΑΣΕΙΣ!$I$2:$I$399,0)),"")) | F23: =IF($G23="","",CHOOSE(WEEKDAY($G23,2),"Δευ","Τρί","Τετ","Πέμ","Παρ","Σάβ","Κυρ")) -> Παρ | G23: =IFERROR(IF(MONTH(DATE($L$8,$L$7,ROW()-3))=$L$7,DATE($L$8,$L$7,ROW()-3),""),"") -> 46346 | H23: =IFERROR(INDEX(ΔΡΑΣΕΙΣ!$D$2:$D$399,MATCH($G23&"#1",ΔΡΑΣΕΙΣ!$I$2:$I$399,0)),"") | I23: =IF($G23="","",IFERROR(INDEX(ΔΡΑΣΕΙΣ!$J$2:$J$399,MATCH($G23&"#1",ΔΡΑΣΕΙΣ!$I$2:$I$399,0)),"")&IFERROR(CHAR(10)&INDEX(ΔΡΑΣΕΙΣ!$J$2:$J$399,MATCH($G23&"#2",ΔΡΑΣΕΙΣ!$I$2:$I$399,0)),"")&IFERROR(CHAR(10)&INDEX(ΔΡΑΣΕΙΣ!$J$2:$J$399,MATCH($G23&"#3",ΔΡΑΣΕΙΣ!$I$2:$I$399,0)),""))
... A34: =IF($B34="","",CHOOSE(WEEKDAY($B34,2),"Δευ","Τρί","Τετ","Πέμ","Παρ","Σάβ","Κυρ")) -> Σάβ | B34: =IFERROR(IF(MONTH(DATE($L$6,$L$5,ROW()-3))=$L$5,DATE($L$6,$L$5,ROW()-3),""),"") -> 46326 | C34: =IFERROR(INDEX(ΔΡΑΣΕΙΣ!$D$2:$D$399,MATCH($B34&"#1",ΔΡΑΣΕΙΣ!$I$2:$I$399,0)),"") | D34: =IF($B34="","",IFERROR(INDEX(ΔΡΑΣΕΙΣ!$J$2:$J$399,MATCH($B34&"#1",ΔΡΑΣΕΙΣ!$I$2:$I$399,0)),"")&IFERROR(CHAR(10)&INDEX(ΔΡΑΣΕΙΣ!$J$2:$J$399,MATCH($B34&"#2",ΔΡΑΣΕΙΣ!$I$2:$I$399,0)),"")&IFERROR(CHAR(10)&INDEX(ΔΡΑΣΕΙΣ!$J$2:$J$399,MATCH($B34&"#3",ΔΡΑΣΕΙΣ!$I$2:$I$399,0)),"")) | F34: =IF($G34="","",CHOOSE(WEEKDAY($G34,2),"Δευ","Τρί","Τετ","Πέμ","Παρ","Σάβ","Κυρ")) | G34: =IFERROR(IF(MONTH(DATE($L$8,$L$7,ROW()-3))=$L$7,DATE($L$8,$L$7,ROW()-3),""),"") | H34: =IFERROR(INDEX(ΔΡΑΣΕΙΣ!$D$2:$D$399,MATCH($G34&"#1",ΔΡΑΣΕΙΣ!$I$2:$I$399,0)),"") | I34: =IF($G34="","",IFERROR(INDEX(ΔΡΑΣΕΙΣ!$J$2:$J$399,MATCH($G34&"#1",ΔΡΑΣΕΙΣ!$I$2:$I$399,0)),"")&IFERROR(CHAR(10)&INDEX(ΔΡΑΣΕΙΣ!$J$2:$J$399,MATCH($G34&"#2",ΔΡΑΣΕΙΣ!$I$2:$I$399,0)),"")&IFERROR(CHAR(10)&INDEX(ΔΡΑΣΕΙΣ!$J$2:$J$399,MATCH($G34&"#3",ΔΡΑΣΕΙΣ!$I$2:$I$399,0)),""))
A36: ΥΠΟΜΝΗΜΑ
B37: Αργία / Διακοπές | G37: Ενημέρωση γονέων / Έλεγχοι
B38: Εορτή / Εκκλησιασμός | G38: Ορόσημο / Εξετάσεις
B39: Εκδρομή / Επίσκεψη / Περίπατος | G39: Επιμόρφωση εκπαιδευτικών
B40: Σύλλογος διδασκόντων | G40: Δράση / Πρόγραμμα / Όμιλος

Sheet ΑΦΙΣΑ_1ΜΗΝΑΣ
A1: =ΟΔΗΓΙΕΣ!$A$1 -> 3ο ΓΥΜΝΑΣΙΟ ΠΟΛΙΧΝΗΣ · ΗΜΕΡΟΛΟΓΙΟ ΔΡΑΣΕΩΝ · ΣΧΟΛΙΚΟ ΕΤΟΣ 2026-27 | K1: ΕΠΙΛΟΓΗ ΜΗΝΑ (βοηθητικά – δεν εκτυπώνονται) | N1: ΜΗΝΑΣ | O1: ΑΡ. | P1: ΕΤΟΣ+
A2: =$L$2&" "&$L$6 -> ΝΟΕΜΒΡΙΟΣ 2026 | K2: Μήνας: | L2: ΝΟΕΜΒΡΙΟΣ | N2: ΣΕΠΤΕΜΒΡΙΟΣ | O2: 9 | P2: 0
A3: ΔΕΥΤΕΡΑ | B3: ΤΡΙΤΗ | C3: ΤΕΤΑΡΤΗ | D3: ΠΕΜΠΤΗ | E3: ΠΑΡΑΣΚΕΥΗ | F3: ΣΑΒΒΑΤΟ | G3: ΚΥΡΙΑΚΗ | N3: ΟΚΤΩΒΡΙΟΣ | O3: 10 | P3: 0
A4: =IF(MONTH($L$7+0)=$L$5,$L$7+0,"") | B4: =IF(MONTH($L$7+1)=$L$5,$L$7+1,"") | C4: =IF(MONTH($L$7+2)=$L$5,$L$7+2,"") | D4: =IF(MONTH($L$7+3)=$L$5,$L$7+3,"") | E4: =IF(MONTH($L$7+4)=$L$5,$L$7+4,"") | F4: =IF(MONTH($L$7+5)=$L$5,$L$7+5,"") | G4: =IF(MONTH($L$7+6)=$L$5,$L$7+6,"") -> 46327 | N4: ΝΟΕΜΒΡΙΟΣ | O4: 11 | P4: 0
A5: =IF(A4="","",IFERROR(INDEX(ΔΡΑΣΕΙΣ!$J$2:$J$399,MATCH(A4&"#1",ΔΡΑΣΕΙΣ!$I$2:$I$399,0)),"")&IFERROR(CHAR(10)&INDEX(ΔΡΑΣΕΙΣ!$J$2:$J$399,MATCH(A4&"#2",ΔΡΑΣΕΙΣ!$I$2:$I$399,0)),"")&IFERROR(CHAR(10)&INDEX(ΔΡΑΣΕΙΣ!$J$2:$J$399,MATCH(A4&"#3",ΔΡΑΣΕΙΣ!$I$2:$I$399,0)),"")) | B5: =IF(B4="","",IFERROR(INDEX(ΔΡΑΣΕΙΣ!$J$2:$J$399,MATCH(B4&"#1",ΔΡΑΣΕΙΣ!$I$2:$I$399,0)),"")&IFERROR(CHAR(10)&INDEX(ΔΡΑΣΕΙΣ!$J$2:$J$399,MATCH(B4&"#2",ΔΡΑΣΕΙΣ!$I$2:$I$399,0)),"")&IFERROR(CHAR(10)&INDEX(ΔΡΑΣΕΙΣ!$J$2:$J$399,MATCH(B4&"#3",ΔΡΑΣΕΙΣ!$I$2:$I$399,0)),"")) | C5: =IF(C4="","",IFERROR(INDEX(ΔΡΑΣΕΙΣ!$J$2:$J$399,MATCH(C4&"#1",ΔΡΑΣΕΙΣ!$I$2:$I$399,0)),"")&IFERROR(CHAR(10)&INDEX(ΔΡΑΣΕΙΣ!$J$2:$J$399,MATCH(C4&"#2",ΔΡΑΣΕΙΣ!$I$2:$I$399,0)),"")&IFERROR(CHAR(10)&INDEX(ΔΡΑΣΕΙΣ!$J$2:$J$399,MATCH(C4&"#3",ΔΡΑΣΕΙΣ!$I$2:$I$399,0)),"")) | D5: =IF(D4="","",IFERROR(INDEX(ΔΡΑΣΕΙΣ!$J$2:$J$399,MATCH(D4&"#1",ΔΡΑΣΕΙΣ!$I$2:$I$399,0)),"")&IFERROR(CHAR(10)&INDEX(ΔΡΑΣΕΙΣ!$J$2:$J$399,MATCH(D4&"#2",ΔΡΑΣΕΙΣ!$I$2:$I$399,0)),"")&IFERROR(CHAR(10)&INDEX(ΔΡΑΣΕΙΣ!$J$2:$J$399,MATCH(D4&"#3",ΔΡΑΣΕΙΣ!$I$2:$I$399,0)),"")) | E5: =IF(E4="","",IFERROR(INDEX(ΔΡΑΣΕΙΣ!$J$2:$J$399,MATCH(E4&"#1",ΔΡΑΣΕΙΣ!$I$2:$I$399,0)),"")&IFERROR(CHAR(10)&INDEX(ΔΡΑΣΕΙΣ!$J$2:$J$399,MATCH(E4&"#2",ΔΡΑΣΕΙΣ!$I$2:$I$399,0)),"")&IFERROR(CHAR(10)&INDEX(ΔΡΑΣΕΙΣ!$J$2:$J$399,MATCH(E4&"#3",ΔΡΑΣΕΙΣ!$I$2:$I$399,0)),"")) | F5: =IF(F4="","",IFERROR(INDEX(ΔΡΑΣΕΙΣ!$J$2:$J$399,MATCH(F4&"#1",ΔΡΑΣΕΙΣ!$I$2:$I$399,0)),"")&IFERROR(CHAR(10)&INDEX(ΔΡΑΣΕΙΣ!$J$2:$J$399,MATCH(F4&"#2",ΔΡΑΣΕΙΣ!$I$2:$I$399,0)),"")&IFERROR(CHAR(10)&INDEX(ΔΡΑΣΕΙΣ!$J$2:$J$399,MATCH(F4&"#3",ΔΡΑΣΕΙΣ!$I$2:$I$399,0)),"")) | G5: =IF(G4="","",IFERROR(INDEX(ΔΡΑΣΕΙΣ!$J$2:$J$399,MATCH(G4&"#1",ΔΡΑΣΕΙΣ!$I$2:$I$399,0)),"")&IFERROR(CHAR(10)&INDEX(ΔΡΑΣΕΙΣ!$J$2:$J$399,MATCH(G4&"#2",ΔΡΑΣΕΙΣ!$I$2:$I$399,0)),"")&IFERROR(CHAR(10)&INDEX(ΔΡΑΣΕΙΣ!$J$2:$J$399,MATCH(G4&"#3",ΔΡΑΣΕΙΣ!$I$2:$I$399,0)),"")) | K5: αρ. μήνα | L5: =INDEX($O$2:$O$11,MATCH($L$2,$N$2:$N$11,0)) -> 11 | N5: ΔΕΚΕΜΒΡΙΟΣ | O5: 12 | P5: 0
K6: έτος | L6: =ΟΔΗΓΙΕΣ!$B$3+INDEX($P$2:$P$11,MATCH($L$2,$N$2:$N$11,0)) -> 2026 | N6: ΙΑΝΟΥΑΡΙΟΣ | O6: 1 | P6: 1
K7: 1η μέρα πλέγματος | L7: =DATE($L$6,$L$5,1)-WEEKDAY(DATE($L$6,$L$5,1),2)+1 -> 46321 | N7: ΦΕΒΡΟΥΑΡΙΟΣ | O7: 2 | P7: 1
N8: ΜΑΡΤΙΟΣ | O8: 3 | P8: 1
A9: =IF(MONTH($L$7+7)=$L$5,$L$7+7,"") -> 46328 | B9: =IF(MONTH($L$7+8)=$L$5,$L$7+8,"") -> 46329 | C9: =IF(MONTH($L$7+9)=$L$5,$L$7+9,"") -> 46330 | D9: =IF(MONTH($L$7+10)=$L$5,$L$7+10,"") -> 46331 | E9: =IF(MONTH($L$7+11)=$L$5,$L$7+11,"") -> 46332 | F9: =IF(MONTH($L$7+12)=$L$5,$L$7+12,"") -> 46333 | G9: =IF(MONTH($L$7+13)=$L$5,$L$7+13,"") -> 46334 | N9: ΑΠΡΙΛΙΟΣ | O9: 4 | P9: 1
A10: =IF(A9="","",IFERROR(INDEX(ΔΡΑΣΕΙΣ!$J$2:$J$399,MATCH(A9&"#1",ΔΡΑΣΕΙΣ!$I$2:$I$399,0)),"")&IFERROR(CHAR(10)&INDEX(ΔΡΑΣΕΙΣ!$J$2:$J$399,MATCH(A9&"#2",ΔΡΑΣΕΙΣ!$I$2:$I$399,0)),"")&IFERROR(CHAR(10)&INDEX(ΔΡΑΣΕΙΣ!$J$2:$J$399,MATCH(A9&"#3",ΔΡΑΣΕΙΣ!$I$2:$I$399,0)),"")) | B10: =IF(B9="","",IFERROR(INDEX(ΔΡΑΣΕΙΣ!$J$2:$J$399,MATCH(B9&"#1",ΔΡΑΣΕΙΣ!$I$2:$I$399,0)),"")&IFERROR(CHAR(10)&INDEX(ΔΡΑΣΕΙΣ!$J$2:$J$399,MATCH(B9&"#2",ΔΡΑΣΕΙΣ!$I$2:$I$399,0)),"")&IFERROR(CHAR(10)&INDEX(ΔΡΑΣΕΙΣ!$J$2:$J$399,MATCH(B9&"#3",ΔΡΑΣΕΙΣ!$I$2:$I$399,0)),"")) | C10: =IF(C9="","",IFERROR(INDEX(ΔΡΑΣΕΙΣ!$J$2:$J$399,MATCH(C9&"#1",ΔΡΑΣΕΙΣ!$I$2:$I$399,0)),"")&IFERROR(CHAR(10)&INDEX(ΔΡΑΣΕΙΣ!$J$2:$J$399,MATCH(C9&"#2",ΔΡΑΣΕΙΣ!$I$2:$I$399,0)),"")&IFERROR(CHAR(10)&INDEX(ΔΡΑΣΕΙΣ!$J$2:$J$399,MATCH(C9&"#3",ΔΡΑΣΕΙΣ!$I$2:$I$399,0)),"")) -> 08:45-11:15 Διαδικτυακή εκπαίδευση «Kids Save Lives» | D10: =IF(D9="","",IFERROR(INDEX(ΔΡΑΣΕΙΣ!$J$2:$J$399,MATCH(D9&"#1",ΔΡΑΣΕΙΣ!$I$2:$I$399,0)),"")&IFERROR(CHAR(10)&INDEX(ΔΡΑΣΕΙΣ!$J$2:$J$399,MATCH(D9&"#2",ΔΡΑΣΕΙΣ!$I$2:$I$399,0)),"")&IFERROR(CHAR(10)&INDEX(ΔΡΑΣΕΙΣ!$J$2:$J$399,MATCH(D9&"#3",ΔΡΑΣΕΙΣ!$I$2:$I$399,0)),"")) | E10: =IF(E9="","",IFERROR(INDEX(ΔΡΑΣΕΙΣ!$J$2:$J$399,MATCH(E9&"#1",ΔΡΑΣΕΙΣ!$I$2:$I$399,0)),"")&IFERROR(CHAR(10)&INDEX(ΔΡΑΣΕΙΣ!$J$2:$J$399,MATCH(E9&"#2",ΔΡΑΣΕΙΣ!$I$2:$I$399,0)),"")&IFERROR(CHAR(10)&INDEX(ΔΡΑΣΕΙΣ!$J$2:$J$399,MATCH(E9&"#3",ΔΡΑΣΕΙΣ!$I$2:$I$399,0)),"")) | F10: =IF(F9="","",IFERROR(INDEX(ΔΡΑΣΕΙΣ!$J$2:$J$399,MATCH(F9&"#1",ΔΡΑΣΕΙΣ!$I$2:$I$399,0)),"")&IFERROR(CHAR(10)&INDEX(ΔΡΑΣΕΙΣ!$J$2:$J$399,MATCH(F9&"#2",ΔΡΑΣΕΙΣ!$I$2:$I$399,0)),"")&IFERROR(CHAR(10)&INDEX(ΔΡΑΣΕΙΣ!$J$2:$J$399,MATCH(F9&"#3",ΔΡΑΣΕΙΣ!$I$2:$I$399,0)),"")) | G10: =IF(G9="","",IFERROR(INDEX(ΔΡΑΣΕΙΣ!$J$2:$J$399,MATCH(G9&"#1",ΔΡΑΣΕΙΣ!$I$2:$I$399,0)),"")&IFERROR(CHAR(10)&INDEX(ΔΡΑΣΕΙΣ!$J$2:$J$399,MATCH(G9&"#2",ΔΡΑΣΕΙΣ!$I$2:$I$399,0)),"")&IFERROR(CHAR(10)&INDEX(ΔΡΑΣΕΙΣ!$J$2:$J$399,MATCH(G9&"#3",ΔΡΑΣΕΙΣ!$I$2:$I$399,0)),"")) | N10: ΜΑΪΟΣ | O10: 5 | P10: 1
N11: ΙΟΥΝΙΟΣ | O11: 6 | P11: 1
A14: =IF(MONTH($L$7+14)=$L$5,$L$7+14,"") -> 46335 | B14: =IF(MONTH($L$7+15)=$L$5,$L$7+15,"") -> 46336 | C14: =IF(MONTH($L$7+16)=$L$5,$L$7+16,"") -> 46337 | D14: =IF(MONTH($L$7+17)=$L$5,$L$7+17,"") -> 46338 | E14: =IF(MONTH($L$7+18)=$L$5,$L$7+18,"") -> 46339 | F14: =IF(MONTH($L$7+19)=$L$5,$L$7+19,"") -> 46340 | G14: =IF(MONTH($L$7+20)=$L$5,$L$7+20,"") -> 46341
A15: =IF(A14="","",IFERROR(INDEX(ΔΡΑΣΕΙΣ!$J$2:$J$399,MATCH(A14&"#1",ΔΡΑΣΕΙΣ!$I$2:$I$399,0)),"")&IFERROR(CHAR(10)&INDEX(ΔΡΑΣΕΙΣ!$J$2:$J$399,MATCH(A14&"#2",ΔΡΑΣΕΙΣ!$I$2:$I$399,0)),"")&IFERROR(CHAR(10)&INDEX(ΔΡΑΣΕΙΣ!$J$2:$J$399,MATCH(A14&"#3",ΔΡΑΣΕΙΣ!$I$2:$I$399,0)),"")) | B15: =IF(B14="","",IFERROR(INDEX(ΔΡΑΣΕΙΣ!$J$2:$J$399,MATCH(B14&"#1",ΔΡΑΣΕΙΣ!$I$2:$I$399,0)),"")&IFERROR(CHAR(10)&INDEX(ΔΡΑΣΕΙΣ!$J$2:$J$399,MATCH(B14&"#2",ΔΡΑΣΕΙΣ!$I$2:$I$399,0)),"")&IFERROR(CHAR(10)&INDEX(ΔΡΑΣΕΙΣ!$J$2:$J$399,MATCH(B14&"#3",ΔΡΑΣΕΙΣ!$I$2:$I$399,0)),"")) | C15: =IF(C14="","",IFERROR(INDEX(ΔΡΑΣΕΙΣ!$J$2:$J$399,MATCH(C14&"#1",ΔΡΑΣΕΙΣ!$I$2:$I$399,0)),"")&IFERROR(CHAR(10)&INDEX(ΔΡΑΣΕΙΣ!$J$2:$J$399,MATCH(C14&"#2",ΔΡΑΣΕΙΣ!$I$2:$I$399,0)),"")&IFERROR(CHAR(10)&INDEX(ΔΡΑΣΕΙΣ!$J$2:$J$399,MATCH(C14&"#3",ΔΡΑΣΕΙΣ!$I$2:$I$399,0)),"")) | D15: =IF(D14="","",IFERROR(INDEX(ΔΡΑΣΕΙΣ!$J$2:$J$399,MATCH(D14&"#1",ΔΡΑΣΕΙΣ!$I$2:$I$399,0)),"")&IFERROR(CHAR(10)&INDEX(ΔΡΑΣΕΙΣ!$J$2:$J$399,MATCH(D14&"#2",ΔΡΑΣΕΙΣ!$I$2:$I$399,0)),"")&IFERROR(CHAR(10)&INDEX(ΔΡΑΣΕΙΣ!$J$2:$J$399,MATCH(D14&"#3",ΔΡΑΣΕΙΣ!$I$2:$I$399,0)),"")) | E15: =IF(E14="","",IFERROR(INDEX(ΔΡΑΣΕΙΣ!$J$2:$J$399,MATCH(E14&"#1",ΔΡΑΣΕΙΣ!$I$2:$I$399,0)),"")&IFERROR(CHAR(10)&INDEX(ΔΡΑΣΕΙΣ!$J$2:$J$399,MATCH(E14&"#2",ΔΡΑΣΕΙΣ!$I$2:$I$399,0)),"")&IFERROR(CHAR(10)&INDEX(ΔΡΑΣΕΙΣ!$J$2:$J$399,MATCH(E14&"#3",ΔΡΑΣΕΙΣ!$I$2:$I$399,0)),"")) | F15: =IF(F14="","",IFERROR(INDEX(ΔΡΑΣΕΙΣ!$J$2:$J$399,MATCH(F14&"#1",ΔΡΑΣΕΙΣ!$I$2:$I$399,0)),"")&IFERROR(CHAR(10)&INDEX(ΔΡΑΣΕΙΣ!$J$2:$J$399,MATCH(F14&"#2",ΔΡΑΣΕΙΣ!$I$2:$I$399,0)),"")&IFERROR(CHAR(10)&INDEX(ΔΡΑΣΕΙΣ!$J$2:$J$399,MATCH(F14&"#3",ΔΡΑΣΕΙΣ!$I$2:$I$399,0)),"")) | G15: =IF(G14="","",IFERROR(INDEX(ΔΡΑΣΕΙΣ!$J$2:$J$399,MATCH(G14&"#1",ΔΡΑΣΕΙΣ!$I$2:$I$399,0)),"")&IFERROR(CHAR(10)&INDEX(ΔΡΑΣΕΙΣ!$J$2:$J$399,MATCH(G14&"#2",ΔΡΑΣΕΙΣ!$I$2:$I$399,0)),"")&IFERROR(CHAR(10)&INDEX(ΔΡΑΣΕΙΣ!$J$2:$J$399,MATCH(G14&"#3",ΔΡΑΣΕΙΣ!$I$2:$I$399,0)),""))
A19: =IF(MONTH($L$7+21)=$L$5,$L$7+21,"") -> 46342 | B19: =IF(MONTH($L$7+22)=$L$5,$L$7+22,"") -> 46343 | C19: =IF(MONTH($L$7+23)=$L$5,$L$7+23,"") -> 46344 | D19: =IF(MONTH($L$7+24)=$L$5,$L$7+24,"") -> 46345 | E19: =IF(MONTH($L$7+25)=$L$5,$L$7+25,"") -> 46346 | F19: =IF(MONTH($L$7+26)=$L$5,$L$7+26,"") -> 46347 | G19: =IF(MONTH($L$7+27)=$L$5,$L$7+27,"") -> 46348
A20: =IF(A19="","",IFERROR(INDEX(ΔΡΑΣΕΙΣ!$J$2:$J$399,MATCH(A19&"#1",ΔΡΑΣΕΙΣ!$I$2:$I$399,0)),"")&IFERROR(CHAR(10)&INDEX(ΔΡΑΣΕΙΣ!$J$2:$J$399,MATCH(A19&"#2",ΔΡΑΣΕΙΣ!$I$2:$I$399,0)),"")&IFERROR(CHAR(10)&INDEX(ΔΡΑΣΕΙΣ!$J$2:$J$399,MATCH(A19&"#3",ΔΡΑΣΕΙΣ!$I$2:$I$399,0)),"")) | B20: =IF(B19="","",IFERROR(INDEX(ΔΡΑΣΕΙΣ!$J$2:$J$399,MATCH(B19&"#1",ΔΡΑΣΕΙΣ!$I$2:$I$399,0)),"")&IFERROR(CHAR(10)&INDEX(ΔΡΑΣΕΙΣ!$J$2:$J$399,MATCH(B19&"#2",ΔΡΑΣΕΙΣ!$I$2:$I$399,0)),"")&IFERROR(CHAR(10)&INDEX(ΔΡΑΣΕΙΣ!$J$2:$J$399,MATCH(B19&"#3",ΔΡΑΣΕΙΣ!$I$2:$I$399,0)),"")) -> Εκδηλώσεις για την επέτειο του Πολυτεχνείου | C20: =IF(C19="","",IFERROR(INDEX(ΔΡΑΣΕΙΣ!$J$2:$J$399,MATCH(C19&"#1",ΔΡΑΣΕΙΣ!$I$2:$I$399,0)),"")&IFERROR(CHAR(10)&INDEX(ΔΡΑΣΕΙΣ!$J$2:$J$399,MATCH(C19&"#2",ΔΡΑΣΕΙΣ!$I$2:$I$399,0)),"")&IFERROR(CHAR(10)&INDEX(ΔΡΑΣΕΙΣ!$J$2:$J$399,MATCH(C19&"#3",ΔΡΑΣΕΙΣ!$I$2:$I$399,0)),"")) | D20: =IF(D19="","",IFERROR(INDEX(ΔΡΑΣΕΙΣ!$J$2:$J$399,MATCH(D19&"#1",ΔΡΑΣΕΙΣ!$I$2:$I$399,0)),"")&IFERROR(CHAR(10)&INDEX(ΔΡΑΣΕΙΣ!$J$2:$J$399,MATCH(D19&"#2",ΔΡΑΣΕΙΣ!$I$2:$I$399,0)),"")&IFERROR(CHAR(10)&INDEX(ΔΡΑΣΕΙΣ!$J$2:$J$399,MATCH(D19&"#3",ΔΡΑΣΕΙΣ!$I$2:$I$399,0)),"")) | E20: =IF(E19="","",IFERROR(INDEX(ΔΡΑΣΕΙΣ!$J$2:$J$399,MATCH(E19&"#1",ΔΡΑΣΕΙΣ!$I$2:$I$399,0)),"")&IFERROR(CHAR(10)&INDEX(ΔΡΑΣΕΙΣ!$J$2:$J$399,MATCH(E19&"#2",ΔΡΑΣΕΙΣ!$I$2:$I$399,0)),"")&IFERROR(CHAR(10)&INDEX(ΔΡΑΣΕΙΣ!$J$2:$J$399,MATCH(E19&"#3",ΔΡΑΣΕΙΣ!$I$2:$I$399,0)),"")) | F20: =IF(F19="","",IFERROR(INDEX(ΔΡΑΣΕΙΣ!$J$2:$J$399,MATCH(F19&"#1",ΔΡΑΣΕΙΣ!$I$2:$I$399,0)),"")&IFERROR(CHAR(10)&INDEX(ΔΡΑΣΕΙΣ!$J$2:$J$399,MATCH(F19&"#2",ΔΡΑΣΕΙΣ!$I$2:$I$399,0)),"")&IFERROR(CHAR(10)&INDEX(ΔΡΑΣΕΙΣ!$J$2:$J$399,MATCH(F19&"#3",ΔΡΑΣΕΙΣ!$I$2:$I$399,0)),"")) | G20: =IF(G19="","",IFERROR(INDEX(ΔΡΑΣΕΙΣ!$J$2:$J$399,MATCH(G19&"#1",ΔΡΑΣΕΙΣ!$I$2:$I$399,0)),"")&IFERROR(CHAR(10)&INDEX(ΔΡΑΣΕΙΣ!$J$2:$J$399,MATCH(G19&"#2",ΔΡΑΣΕΙΣ!$I$2:$I$399,0)),"")&IFERROR(CHAR(10)&INDEX(ΔΡΑΣΕΙΣ!$J$2:$J$399,MATCH(G19&"#3",ΔΡΑΣΕΙΣ!$I$2:$I$399,0)),""))
A24: =IF(MONTH($L$7+28)=$L$5,$L$7+28,"") -> 46349 | B24: =IF(MONTH($L$7+29)=$L$5,$L$7+29,"") -> 46350 | C24: =IF(MONTH($L$7+30)=$L$5,$L$7+30,"") -> 46351 | D24: =IF(MONTH($L$7+31)=$L$5,$L$7+31,"") -> 46352 | E24: =IF(MONTH($L$7+32)=$L$5,$L$7+32,"") -> 46353 | F24: =IF(MONTH($L$7+33)=$L$5,$L$7+33,"") -> 46354 | G24: =IF(MONTH($L$7+34)=$L$5,$L$7+34,"") -> 46355
A25: =IF(A24="","",IFERROR(INDEX(ΔΡΑΣΕΙΣ!$J$2:$J$399,MATCH(A24&"#1",ΔΡΑΣΕΙΣ!$I$2:$I$399,0)),"")&IFERROR(CHAR(10)&INDEX(ΔΡΑΣΕΙΣ!$J$2:$J$399,MATCH(A24&"#2",ΔΡΑΣΕΙΣ!$I$2:$I$399,0)),"")&IFERROR(CHAR(10)&INDEX(ΔΡΑΣΕΙΣ!$J$2:$J$399,MATCH(A24&"#3",ΔΡΑΣΕΙΣ!$I$2:$I$399,0)),"")) | B25: =IF(B24="","",IFERROR(INDEX(ΔΡΑΣΕΙΣ!$J$2:$J$399,MATCH(B24&"#1",ΔΡΑΣΕΙΣ!$I$2:$I$399,0)),"")&IFERROR(CHAR(10)&INDEX(ΔΡΑΣΕΙΣ!$J$2:$J$399,MATCH(B24&"#2",ΔΡΑΣΕΙΣ!$I$2:$I$399,0)),"")&IFERROR(CHAR(10)&INDEX(ΔΡΑΣΕΙΣ!$J$2:$J$399,MATCH(B24&"#3",ΔΡΑΣΕΙΣ!$I$2:$I$399,0)),"")) | C25: =IF(C24="","",IFERROR(INDEX(ΔΡΑΣΕΙΣ!$J$2:$J$399,MATCH(C24&"#1",ΔΡΑΣΕΙΣ!$I$2:$I$399,0)),"")&IFERROR(CHAR(10)&INDEX(ΔΡΑΣΕΙΣ!$J$2:$J$399,MATCH(C24&"#2",ΔΡΑΣΕΙΣ!$I$2:$I$399,0)),"")&IFERROR(CHAR(10)&INDEX(ΔΡΑΣΕΙΣ!$J$2:$J$399,MATCH(C24&"#3",ΔΡΑΣΕΙΣ!$I$2:$I$399,0)),"")) | D25: =IF(D24="","",IFERROR(INDEX(ΔΡΑΣΕΙΣ!$J$2:$J$399,MATCH(D24&"#1",ΔΡΑΣΕΙΣ!$I$2:$I$399,0)),"")&IFERROR(CHAR(10)&INDEX(ΔΡΑΣΕΙΣ!$J$2:$J$399,MATCH(D24&"#2",ΔΡΑΣΕΙΣ!$I$2:$I$399,0)),"")&IFERROR(CHAR(10)&INDEX(ΔΡΑΣΕΙΣ!$J$2:$J$399,MATCH(D24&"#3",ΔΡΑΣΕΙΣ!$I$2:$I$399,0)),"")) | E25: =IF(E24="","",IFERROR(INDEX(ΔΡΑΣΕΙΣ!$J$2:$J$399,MATCH(E24&"#1",ΔΡΑΣΕΙΣ!$I$2:$I$399,0)),"")&IFERROR(CHAR(10)&INDEX(ΔΡΑΣΕΙΣ!$J$2:$J$399,MATCH(E24&"#2",ΔΡΑΣΕΙΣ!$I$2:$I$399,0)),"")&IFERROR(CHAR(10)&INDEX(ΔΡΑΣΕΙΣ!$J$2:$J$399,MATCH(E24&"#3",ΔΡΑΣΕΙΣ!$I$2:$I$399,0)),"")) | F25: =IF(F24="","",IFERROR(INDEX(ΔΡΑΣΕΙΣ!$J$2:$J$399,MATCH(F24&"#1",ΔΡΑΣΕΙΣ!$I$2:$I$399,0)),"")&IFERROR(CHAR(10)&INDEX(ΔΡΑΣΕΙΣ!$J$2:$J$399,MATCH(F24&"#2",ΔΡΑΣΕΙΣ!$I$2:$I$399,0)),"")&IFERROR(CHAR(10)&INDEX(ΔΡΑΣΕΙΣ!$J$2:$J$399,MATCH(F24&"#3",ΔΡΑΣΕΙΣ!$I$2:$I$399,0)),"")) | G25: =IF(G24="","",IFERROR(INDEX(ΔΡΑΣΕΙΣ!$J$2:$J$399,MATCH(G24&"#1",ΔΡΑΣΕΙΣ!$I$2:$I$399,0)),"")&IFERROR(CHAR(10)&INDEX(ΔΡΑΣΕΙΣ!$J$2:$J$399,MATCH(G24&"#2",ΔΡΑΣΕΙΣ!$I$2:$I$399,0)),"")&IFERROR(CHAR(10)&INDEX(ΔΡΑΣΕΙΣ!$J$2:$J$399,MATCH(G24&"#3",ΔΡΑΣΕΙΣ!$I$2:$I$399,0)),""))
A29: =IF(MONTH($L$7+35)=$L$5,$L$7+35,"") -> 46356 | B29: =IF(MONTH($L$7+36)=$L$5,$L$7+36,"") | C29: =IF(MONTH($L$7+37)=$L$5,$L$7+37,"") | D29: =IF(MONTH($L$7+38)=$L$5,$L$7+38,"") | E29: =IF(MONTH($L$7+39)=$L$5,$L$7+39,"") | F29: =IF(MONTH($L$7+40)=$L$5,$L$7+40,"") | G29: =IF(MONTH($L$7+41)=$L$5,$L$7+41,"")
A30: =IF(A29="","",IFERROR(INDEX(ΔΡΑΣΕΙΣ!$J$2:$J$399,MATCH(A29&"#1",ΔΡΑΣΕΙΣ!$I$2:$I$399,0)),"")&IFERROR(CHAR(10)&INDEX(ΔΡΑΣΕΙΣ!$J$2:$J$399,MATCH(A29&"#2",ΔΡΑΣΕΙΣ!$I$2:$I$399,0)),"")&IFERROR(CHAR(10)&INDEX(ΔΡΑΣΕΙΣ!$J$2:$J$399,MATCH(A29&"#3",ΔΡΑΣΕΙΣ!$I$2:$I$399,0)),"")) -> 09:00-12.30 Μουσείο Μακεδονικού Αγώνα | B30: =IF(B29="","",IFERROR(INDEX(ΔΡΑΣΕΙΣ!$J$2:$J$399,MATCH(B29&"#1",ΔΡΑΣΕΙΣ!$I$2:$I$399,0)),"")&IFERROR(CHAR(10)&INDEX(ΔΡΑΣΕΙΣ!$J$2:$J$399,MATCH(B29&"#2",ΔΡΑΣΕΙΣ!$I$2:$I$399,0)),"")&IFERROR(CHAR(10)&INDEX(ΔΡΑΣΕΙΣ!$J$2:$J$399,MATCH(B29&"#3",ΔΡΑΣΕΙΣ!$I$2:$I$399,0)),"")) | C30: =IF(C29="","",IFERROR(INDEX(ΔΡΑΣΕΙΣ!$J$2:$J$399,MATCH(C29&"#1",ΔΡΑΣΕΙΣ!$I$2:$I$399,0)),"")&IFERROR(CHAR(10)&INDEX(ΔΡΑΣΕΙΣ!$J$2:$J$399,MATCH(C29&"#2",ΔΡΑΣΕΙΣ!$I$2:$I$399,0)),"")&IFERROR(CHAR(10)&INDEX(ΔΡΑΣΕΙΣ!$J$2:$J$399,MATCH(C29&"#3",ΔΡΑΣΕΙΣ!$I$2:$I$399,0)),"")) | D30: =IF(D29="","",IFERROR(INDEX(ΔΡΑΣΕΙΣ!$J$2:$J$399,MATCH(D29&"#1",ΔΡΑΣΕΙΣ!$I$2:$I$399,0)),"")&IFERROR(CHAR(10)&INDEX(ΔΡΑΣΕΙΣ!$J$2:$J$399,MATCH(D29&"#2",ΔΡΑΣΕΙΣ!$I$2:$I$399,0)),"")&IFERROR(CHAR(10)&INDEX(ΔΡΑΣΕΙΣ!$J$2:$J$399,MATCH(D29&"#3",ΔΡΑΣΕΙΣ!$I$2:$I$399,0)),"")) | E30: =IF(E29="","",IFERROR(INDEX(ΔΡΑΣΕΙΣ!$J$2:$J$399,MATCH(E29&"#1",ΔΡΑΣΕΙΣ!$I$2:$I$399,0)),"")&IFERROR(CHAR(10)&INDEX(ΔΡΑΣΕΙΣ!$J$2:$J$399,MATCH(E29&"#2",ΔΡΑΣΕΙΣ!$I$2:$I$399,0)),"")&IFERROR(CHAR(10)&INDEX(ΔΡΑΣΕΙΣ!$J$2:$J$399,MATCH(E29&"#3",ΔΡΑΣΕΙΣ!$I$2:$I$399,0)),"")) | F30: =IF(F29="","",IFERROR(INDEX(ΔΡΑΣΕΙΣ!$J$2:$J$399,MATCH(F29&"#1",ΔΡΑΣΕΙΣ!$I$2:$I$399,0)),"")&IFERROR(CHAR(10)&INDEX(ΔΡΑΣΕΙΣ!$J$2:$J$399,MATCH(F29&"#2",ΔΡΑΣΕΙΣ!$I$2:$I$399,0)),"")&IFERROR(CHAR(10)&INDEX(ΔΡΑΣΕΙΣ!$J$2:$J$399,MATCH(F29&"#3",ΔΡΑΣΕΙΣ!$I$2:$I$399,0)),"")) | G30: =IF(G29="","",IFERROR(INDEX(ΔΡΑΣΕΙΣ!$J$2:$J$399,MATCH(G29&"#1",ΔΡΑΣΕΙΣ!$I$2:$I$399,0)),"")&IFERROR(CHAR(10)&INDEX(ΔΡΑΣΕΙΣ!$J$2:$J$399,MATCH(G29&"#2",ΔΡΑΣΕΙΣ!$I$2:$I$399,0)),"")&IFERROR(CHAR(10)&INDEX(ΔΡΑΣΕΙΣ!$J$2:$J$399,MATCH(G29&"#3",ΔΡΑΣΕΙΣ!$I$2:$I$399,0)),""))
A35: ΥΠΟΜΝΗΜΑ | E35: ΣΗΜΕΙΩΣΕΙΣ ΜΗΝΑ
A36: =ΚΑΤΗΓΟΡΙΕΣ!$A$2 -> Αργία / Διακοπές | B36: =ΚΑΤΗΓΟΡΙΕΣ!$A$3 -> Εορτή / Εκκλησιασμός | C36: =ΚΑΤΗΓΟΡΙΕΣ!$A$4 -> Εκδρομή / Επίσκεψη / Περίπατος | D36: =ΚΑΤΗΓΟΡΙΕΣ!$A$5 -> Σύλλογος διδασκόντων
A37: =ΚΑΤΗΓΟΡΙΕΣ!$A$6 -> Ενημέρωση γονέων / Έλεγχοι | B37: =ΚΑΤΗΓΟΡΙΕΣ!$A$7 -> Ορόσημο / Εξετάσεις | C37: =ΚΑΤΗΓΟΡΙΕΣ!$A$8 -> Επιμόρφωση εκπαιδευτικών | D37: =ΚΑΤΗΓΟΡΙΕΣ!$A$9 -> Δράση / Πρόγραμμα / Όμιλος

Sheet ΑΦΙΣΑ_1ΜΗΝΑΣ_λίστα
A1: 3ο ΓΥΜΝΑΣΙΟ ΠΟΛΙΧΝΗΣ · ΗΜΕΡΟΛΟΓΙΟ ΔΡΑΣΕΩΝ · ΣΧΟΛΙΚΟ ΕΤΟΣ 2026-27 | F1: ΕΠΙΛΟΓΗ ΜΗΝΑ (βοηθητικά – δεν εκτυπώνονται) | I1: ΜΗΝΑΣ | J1: ΑΡ. | K1: ΕΤΟΣ+
A2: =$G$2&" "&$G$6 -> ΝΟΕΜΒΡΙΟΣ 2026 | F2: Μήνας: | G2: ΝΟΕΜΒΡΙΟΣ | I2: ΣΕΠΤΕΜΒΡΙΟΣ | J2: 9 | K2: 0
A3: ΗΜΕΡΑ | B3: ΗΜ/ΝΙΑ | C3: ΚΑΤΗΓΟΡΙΑ | D3: ΔΡΑΣΕΙΣ ΤΗΣ ΗΜΕΡΑΣ | I3: ΟΚΤΩΒΡΙΟΣ | J3: 10 | K3: 0
A4: =IF($B4="","",CHOOSE(WEEKDAY($B4,2),"Δευ","Τρί","Τετ","Πέμ","Παρ","Σάβ","Κυρ")) -> Κυρ | B4: =IFERROR(IF(MONTH(DATE($G$6,$G$5,ROW()-3))=$G$5,DATE($G$6,$G$5,ROW()-3),""),"") -> 46327 | C4: =IFERROR(INDEX(ΔΡΑΣΕΙΣ!$D$2:$D$399,MATCH($B4&"#1",ΔΡΑΣΕΙΣ!$I$2:$I$399,0)),"") | D4: =IF($B4="","",IFERROR(INDEX(ΔΡΑΣΕΙΣ!$J$2:$J$399,MATCH($B4&"#1",ΔΡΑΣΕΙΣ!$I$2:$I$399,0)),"")&IFERROR(CHAR(10)&INDEX(ΔΡΑΣΕΙΣ!$J$2:$J$399,MATCH($B4&"#2",ΔΡΑΣΕΙΣ!$I$2:$I$399,0)),"")&IFERROR(CHAR(10)&INDEX(ΔΡΑΣΕΙΣ!$J$2:$J$399,MATCH($B4&"#3",ΔΡΑΣΕΙΣ!$I$2:$I$399,0)),"")) | I4: ΝΟΕΜΒΡΙΟΣ | J4: 11 | K4: 0
A5: =IF($B5="","",CHOOSE(WEEKDAY($B5,2),"Δευ","Τρί","Τετ","Πέμ","Παρ","Σάβ","Κυρ")) -> Δευ | B5: =IFERROR(IF(MONTH(DATE($G$6,$G$5,ROW()-3))=$G$5,DATE($G$6,$G$5,ROW()-3),""),"") -> 46328 | C5: =IFERROR(INDEX(ΔΡΑΣΕΙΣ!$D$2:$D$399,MATCH($B5&"#1",ΔΡΑΣΕΙΣ!$I$2:$I$399,0)),"") | D5: =IF($B5="","",IFERROR(INDEX(ΔΡΑΣΕΙΣ!$J$2:$J$399,MATCH($B5&"#1",ΔΡΑΣΕΙΣ!$I$2:$I$399,0)),"")&IFERROR(CHAR(10)&INDEX(ΔΡΑΣΕΙΣ!$J$2:$J$399,MATCH($B5&"#2",ΔΡΑΣΕΙΣ!$I$2:$I$399,0)),"")&IFERROR(CHAR(10)&INDEX(ΔΡΑΣΕΙΣ!$J$2:$J$399,MATCH($B5&"#3",ΔΡΑΣΕΙΣ!$I$2:$I$399,0)),"")) | F5: αρ. μήνα Α | G5: =INDEX($J$2:$J$11,MATCH($G$2,$I$2:$I$11,0)) -> 11 | I5: ΔΕΚΕΜΒΡΙΟΣ | J5: 12 | K5: 0
